Workbook
Name 切片器_订单状态: #N/A

Sheet Sheet1
A3: 行标签 | B3: 计数项:订单编号
A4: DD-20260512-0102 | B4: 2
A5: DD-20260603-0126 | B5: 2
A6: 总计 | B6: 4

Sheet Sheet3
A3: #VALUE!
A59: 行标签 | B59: 求和项:金额(修正后)
A60: A | B60: 979267
A61: 办公耗材 | B61: 247993
A62: 办公设备 | B62: 178827
A63: 电子数码 | B63: 353638
A64: 软件服务 | B64: 198809
A65: B | B65: 1090774
A66: 办公耗材 | B66: 319871
A67: 办公设备 | B67: 117840
A68: 电子数码 | B68: 492909
A69: 软件服务 | B69: 160154
A70: C | B70: 911286
A71: 办公耗材 | B71: 323083
... A75: 总计 | B75: 2981327
A84: 行标签 | B84: 求和项:金额(修正后)
A85: A | B85: 979267
A86: 办公耗材 | B86: 247993
A87: 办公设备 | B87: 178827
A88: 电子数码 | B88: 353638
A89: 软件服务 | B89: 198809
A90: B | B90: 1090774
A91: 办公耗材 | B91: 319871
A92: 办公设备 | B92: 117840
A93: 电子数码 | B93: 492909
A94: 软件服务 | B94: 160154
A95: C | B95: 911286
A96: 办公耗材 | B96: 323083
... A100: 总计 | B100: 2981327

Sheet 统计计算
A3: 行标签 | B3: 计数项:订单编号 | C3: 求和项:金额(修正后)
A4: 待付款 | B4: 24 | C4: 346554
A5: 已发货 | B5: 47 | C5: 641423
A6: 已取消 | B6: 19 | C6: 291512
A7: 已完成 | B7: 112 | C7: 1701838
A8: (空白)
A9: 总计 | B9: 202 | C9: 2981327
A19: 行标签 | B19: 平均值项:金额(修正后)
A20: 陈静 | B20: 17359.364
A21: 李娜 | B21: 12536.56
A22: 刘洋 | B22: 8105.1333
A23: 孙悦 | B23: 15897.773
A24: 王强 | B24: 19083.818
A25: 杨帆 | B25: 11349.273
A26: 张伟 | B26: 17490.2
A27: 赵磊 | B27: 13804.586
A28: 总计 | B28: 14698.443
A36: 求和项:金额(修正后) | B36: 列标签
B37: 1月 | P37: 1月 汇总 | Q37: 2月 | X37: 2月 汇总 | Y37: 3月 | AK37: 3月 汇总 | AL37: 4月 | BB37: 4月 汇总 | BC37: 5月 | BY37: 5月 汇总 | BZ37: 6月 | CQ37: 6月 汇总 | CR37: 7月 | DK37: 7月 汇总 | DL37: 8月 | DZ37: 8月 汇总 | EA37: 总计
A38: 行标签 | B38: 46025 | C38: 46029 | D38: 46031 | E38: 46035 | F38: 46039 | G38: 46042 | H38: 46045 | I38: 46046 | J38: 46047 | K38: 46048 | L38: 46049 | M38: 46051 | N38: 46052 | O38: 46053 | Q38: 46056 | R38: 46059 | S38: 46061 | T38: 46069 | U38: 46074 | V38: 46076 | W38: 46080 | Y38: 46084 | Z38: 46087 | AA38: 46089 | AB38: 46091 | AC38: 46096 | AD38: 46097 | AE38: 46098 | AF38: 46102 | AG38: 46103 | AH38: 46104 | AI38: 46110 | AJ38: 46112 | AL38: 46114 | AM38: 46115 | AN38: 46117 | AO38: 46124 | AP38: 46125 | AQ38: 46130 | AR38: 46131 | AS38: 46132 | AT38: 46133 | AU38: 46134 | AV38: 46135 | AW38: 46138 | AX38: 46139 | AY38: 46140 | AZ38: 46141 | BA38: 46142 | BC38: 46143 | BD38: 46145 | BE38: 46146 | BF38: 46148 | BG38: 46150 | BH38: 46151 | BI38: 46152 | BJ38: 46153 | BK38: 46154 | BL38: 46155 | BM38: 46156 | BN38: 46157 | BO38: 46160 | BP38: 46162 | BQ38: 46163 | BR38: 46164 | BS38: 46165 | BT38: 46166 | BU38: 46167 | BV38: 46169 | BW38: 46170 | BX38: 46173 | BZ38: 46175 | CA38: 46176 | CB38: 46180 | CC38: 46182 | CD38: 46183 | CE38: 46186 | CF38: 46188 | CG38: 46189 | CH38: 46192 | CI38: 46194 | CJ38: 46195 | CK38: 46196 | CL38: 46199 | CM38: 46200 | CN38: 46201 | CO38: 46202 | CP38: 46203 | CR38: 46204 | CS38: 46205 | CT38: 46206 | CU38: 46208 | CV38: 46209 | CW38: 46210 | CX38: 46213 | CY38: 46215 | CZ38: 46219 | DA38: 46220 | DB38: 46221 | DC38: 46223 | DD38: 46227 | DE38: 46228 | DF38: 46229 | DG38: 46230 | DH38: 46231 | DI38: 46232 | DJ38: 46234 | DL38: 46235 | DM38: 46238 | DN38: 46239 | DO38: 46240 | DP38: 46243 | DQ38: 46244 | DR38: 46245 | DS38: 46247 | DT38: 46248 | DU38: 46249 | DV38: 46250 | DW38: 46251 | DX38: 46252 | DY38: 46254
A39: 华北 | D39: 3825 | G39: 1797 | J39: 12320 | K39: 9996 | P39: 27938 | V39: 28495 | X39: 28495 | Z39: 15588 | AA39: 7188 | AC39: 22163 | AH39: 27261 | AK39: 72200 | AP39: 15588 | AS39: 6293 | BB39: 21881 | BE39: 2944 | BF39: 11691 | BG39: 2598 | BH39: 22762 | BL39: 10010 | BQ39: 14592 | BR39: 17097 | BS39: 5196 | BT39: 9240 | BX39: 6495 | BY39: 102625 | CA39: 68381 | CC39: 9625 | CI39: 34087 | CP39: 2691 | CQ39: 114784 | CT39: 48142 | CY39: 7497 | DF39: 53515 | DK39: 109154 | DO39: 2093 | DQ39: 22163 | DS39: 8576 | DU39: 7497 | DZ39: 40329 | EA39: 517406
A40: 华东 | B40: 2691 | F40: 3495 | M40: 13980 | N40: 2691 | P40: 22857 | R40: 4635 | S40: 598 | T40: 62689 | U40: 13980 | X40: 81902 | Z40: 15588 | AA40: 15825 | AB40: 17097 | AD40: 50265 | AE40: 765 | AG40: 17475 | AJ40: 15588 | AK40: 132603 | AM40: 1299 | AN40: 10523 | AP40: 38500 | AR40: 2990 | AV40: 13312 | AW40: 30289 | AX40: 34392 | AY40: 9093 | BB40: 140398 | BF40: 14994 | BI40: 6990 | BJ40: 23067 | BK40: 131077 | BM40: 4365 | BO40: 675 | BP40: 12800 | BQ40: 8388 | BS40: 23960 | BU40: 20271 | BY40: 246587 | CA40: 3599 | CD40: 6528 | CF40: 25410 | CG40: 15378 | CH40: 5196 | CO40: 3596 | CP40: 39893 | CQ40: 99600 | CU40: 2990 | DA40: 18174 | DB40: 12579 | DC40: 68388 | DE40: 2990 | DF40: 8448 | DG40: 14976 | DH40: 23766 | DI40: 17493 | DK40: 169804 | DL40: 897 | DM40: 35035 | DN40: 5592 | DS40: 7497 | DT40: 5248 | DW40: 34392 | DZ40: 88661 | EA40: 982412
A41: 华南 | B41: 899 | P41: 899 | AC41: 5699 | AF41: 1794 | AK41: 7493 | AL41: 1797 | AQ41: 21594 | AR41: 28792 | AT41: 28105 | AU41: 3588 | AY41: 12288 | BA41: 22368 | BB41: 118532 | BC41: 39565 | BD41: 31559 | BF41: 20405 | BK41: 26562 | BS41: 1080 | BV41: 13281 | BY41: 132452 | CB41: 1299 | CC41: 2097 | CF41: 3465 | CJ41: 10797 | CL41: 19168 | CM41: 14396 | CQ41: 51222 | CW41: 5196 | CY41: 3840 | CZ41: 20360 | DD41: 3588 | DJ41: 11883 | DK41: 44867 | DL41: 5592 | DP41: 14396 | DR41: 19992 | DU41: 7699 | DZ41: 47679 | EA41: 403144
A42: 华中 | C42: 5394 | D42: 2560 | E42: 3596 | K42: 3596 | L42: 19190 | O42: 11398 | P42: 45734 | Y42: 46200 | AH42: 899 | AK42: 47099 | AY42: 25193 | BB42: 25193 | BF42: 25794 | BG42: 24465 | BK42: 21495 | BM42: 1797 | BW42: 8704 | BY42: 82255 | CE42: 15104 | CK42: 25863 | CN42: 5504 | CQ42: 46471 | CR42: 2697 | CZ42: 598 | DC42: 1794 | DE42: 18480 | DK42: 23569 | DM42: 2816 | DU42: 12990 | DW42: 51588 | DY42: 9996 | DZ42: 77390 | EA42: 347711
A43: 西南 | H43: 7689 | I43: 36960 | P43: 44649 | Q43: 3596 | R43: 10010 | W43: 14376 | X43: 27982 | AB43: 9093 | AI43: 42735 | AK43: 51828 | AO43: 4905 | AQ43: 17995 | AR43: 6291 | AV43: 27261 | AZ43: 25794 | BB43: 82246 | BK43: 14289 | BN43: 8832 | BY43: 23121 | BZ43: 24465 | CF43: 27335 | CQ43: 51800 | CS43: 47289 | CV43: 3825 | CX43: 7787 | DF43: 10183 | DI43: 20790 | DK43: 89874 | DO43: 51291 | DV43: 9856 | DX43: 6495 | DZ43: 67642 | EA43: 439142
A44: 总计 | B44: 3590 | C44: 5394 | D44: 6385 | E44: 3596 | F44: 3495 | G44: 1797 | H44: 7689 | I44: 36960 | J44: 12320 | K44: 13592 | L44: 19190 | M44: 13980 | N44: 2691 | O44: 11398 | P44: 142077 | Q44: 3596 | R44: 14645 | S44: 598 | T44: 62689 | U44: 13980 | V44: 28495 | W44: 14376 | X44: 138379 | Y44: 46200 | Z44: 31176 | AA44: 23013 | AB44: 26190 | AC44: 27862 | AD44: 50265 | AE44: 765 | AF44: 1794 | AG44: 17475 | AH44: 28160 | AI44: 42735 | AJ44: 15588 | AK44: 311223 | AL44: 1797 | AM44: 1299 | AN44: 10523 | AO44: 4905 | AP44: 54088 | AQ44: 39589 | AR44: 38073 | AS44: 6293 | AT44: 28105 | AU44: 3588 | AV44: 40573 | AW44: 30289 | AX44: 34392 | AY44: 46574 | AZ44: 25794 | BA44: 22368 | BB44: 388250 | BC44: 39565 | BD44: 31559 | BE44: 2944 | BF44: 72884 | BG44: 27063 | BH44: 22762 | BI44: 6990 | BJ44: 23067 | BK44: 193423 | BL44: 10010 | BM44: 6162 | BN44: 8832 | BO44: 675 | BP44: 12800 | BQ44: 22980 | BR44: 17097 | BS44: 30236 | BT44: 9240 | BU44: 20271 | BV44: 13281 | BW44: 8704 | BX44: 6495 | BY44: 587040 | BZ44: 24465 | CA44: 71980 | CB44: 1299 | CC44: 11722 | CD44: 6528 | CE44: 15104 | CF44: 56210 | CG44: 15378 | CH44: 5196 | CI44: 34087 | CJ44: 10797 | CK44: 25863 | CL44: 19168 | CM44: 14396 | CN44: 5504 | CO44: 3596 | CP44: 42584 | CQ44: 363877 | CR44: 2697 | CS44: 47289 | CT44: 48142 | CU44: 2990 | CV44: 3825 | CW44: 5196 | CX44: 7787 | CY44: 11337 | CZ44: 20958 | DA44: 18174 | DB44: 12579 | DC44: 70182 | DD44: 3588 | DE44: 21470 | DF44: 72146 | DG44: 14976 | DH44: 23766 | DI44: 38283 | DJ44: 11883 | DK44: 437268 | DL44: 6489 | DM44: 37851 | DN44: 5592 | DO44: 53384 | DP44: 14396 | DQ44: 22163 | DR44: 19992 | DS44: 16073 | DT44: 5248 | DU44: 28186 | DV44: 9856 | DW44: 85980 | DX44: 6495 | DY44: 9996 | DZ44: 321701 | EA44: 2689815

Sheet Sheet5
A3: 月(日期) | B3: 求和项:金额(修正后) | C3: 求和项:金额(修正后)2
A4: 1月 | B4: 161324
A5: 2月 | B5: 235656 | C5: 0.46076219
A6: 3月 | B6: 321219 | C6: 0.36308433
A7: 4月 | B7: 407561 | C7: 0.26879481
A8: 5月 | B8: 699396 | C8: 0.71605232
A9: 6月 | B9: 390909 | C9: -0.4410763
A10: 7月 | B10: 443561 | C10: 0.13469119
A11: 8月 | B11: 321701 | C11: -0.2747311

Sheet 订单表_原始
A1: 订单编号 | B1: 下单日期 | C1: 下单日期(修正后) | D1: 客户ID | E1: 客户名称(修正后) | F1: 客户名称 | G1: 客户ID(修正后) | H1: 产品类别 | I1: 日期 | J1: 流水号 | K1: 用户登记（修正后） | L1: 销售员 | M1: 区域 | N1: 区域(修正后) | O1: 产品编码 | P1: 产品名称 | Q1: 单价(元) | R1: 数量 | S1: 修正后 | T1: 折扣(修正后) | U1: 金额(元) | V1: 金额(修正后) | W1: 订单状态 | X1: 应收金额 | Y1: 成本 | Z1: 毛利率
A2: DD-20260101-0001 | B2: 46023 | C2: =TEXT(SUBSTITUTE(B2,".","/"),"yyyy-mm-dd") -> 2026-01-01 | D2: KH003 | E2: =VLOOKUP(D2,客户信息表!A$3:H$23,2,0) -> 广州启航教育 | F2: 广州启航教育 | G2: =INDEX(客户信息表!$A$4:$H$23,MATCH(F2,客户信息表!$B$4:$B$23,0),1) -> KH003 | H2: =_xlfn.XLOOKUP(O2,产品信息表!$A$4:$A$15,产品信息表!$C$4:$C$15) -> 软件服务 | I2: =DATE(MID(A2,4,4),MID(A2,8,2),MID(A2,10,2)) -> 46023 | J2: =RIGHT(A2,4) -> 0001 | K2: =VLOOKUP(D2,客户信息表!$A$3:$H$23,5,0) -> A | L2: 孙悦 | M2: 华南 | N2: =SUBSTITUTE(TRIM(M2),"区","") -> 华南 | O2: CP011 | P2: 办公软件年费授权 | Q2: 699 | S2: =IF(ISBLANK(R2),U2/Q2,VALUE(R2)) -> 11 | T2: =VLOOKUP(S2,折扣阶梯!$A$3:$C$7,2,TRUE) -> 0.95 | U2: 7689 | V2: =IF(Q2*S2=VALUE(SUBSTITUTE(U2,"¥","")),VALUE(SUBSTITUTE(U2,"¥","")),Q2*S2) -> 7689 | W2: 已取消 | X2: =V2*T2 -> 7304.55 | Y2: =_xlfn.XLOOKUP(O2,产品信息表!$A$4:$A$15,产品信息表!$E$4:$E$15) -> 300 | Z2: =(X2-Y2*S2)/X2 -> 0.54822679 | AA2: =_xlfn.RANK.EQ(V2,V2:V203,0) -> 117
A3: DD-20260103-0002 | B3: 46025 | C3: =TEXT(SUBSTITUTE(B3,".","/"),"yyyy-mm-dd") -> 2026-01-03 | D3: KH002 | E3: =VLOOKUP(D3,客户信息表!A$3:H$23,2,0) -> 上海锦程贸易 | F3: 上海锦程贸易 | G3: =INDEX(客户信息表!$A$4:$H$23,MATCH(F3,客户信息表!$B$4:$B$23,0),1) -> KH002 | H3: =_xlfn.XLOOKUP(O3,产品信息表!$A$4:$A$15,产品信息表!$C$4:$C$15) -> 电子数码 | I3: =DATE(MID(A3,4,4),MID(A3,8,2),MID(A3,10,2)) -> 46025 | J3: =RIGHT(A3,4) -> 0002 | K3: =VLOOKUP(D3,客户信息表!$A$3:$H$23,5,0) -> B | L3: 李娜 | M3: 华东 | N3: =SUBSTITUTE(TRIM(M3),"区","") -> 华东 | O3: CP007 | P3: 无线键鼠套装 KeyFree 2.0 | Q3: 299 | R3: 9 | S3: =IF(ISBLANK(R3),U3/Q3,VALUE(R3)) -> 9 | T3: =VLOOKUP(S3,折扣阶梯!$A$3:$C$7,2,TRUE) -> 1 | U3: 2691 | V3: =IF(Q3*S3=VALUE(SUBSTITUTE(U3,"¥","")),VALUE(SUBSTITUTE(U3,"¥","")),Q3*S3) -> 2691 | W3: 已发货 | X3: =V3*T3 -> 2691 | Y3: =_xlfn.XLOOKUP(O3,产品信息表!$A$4:$A$15,产品信息表!$E$4:$E$15) -> 190 | Z3: =(X3-Y3*S3)/X3 -> 0.36454849 | AA3: =_xlfn.RANK.EQ(V3,V3:V204,0) -> 174
A4: DD-20260103-0003 | B4: 46025 | C4: =TEXT(SUBSTITUTE(B4,".","/"),"yyyy-mm-dd") -> 2026-01-03 | D4: KH003 | E4: =VLOOKUP(D4,客户信息表!A$3:H$23,2,0) -> 广州启航教育 | F4: 广州启航教育 | G4: =INDEX(客户信息表!$A$4:$H$23,MATCH(F4,客户信息表!$B$4:$B$23,0),1) -> KH003 | H4: =_xlfn.XLOOKUP(O4,产品信息表!$A$4:$A$15,产品信息表!$C$4:$C$15) -> 办公设备 | I4: =DATE(MID(A4,4,4),MID(A4,8,2),MID(A4,10,2)) -> 46025 | J4: =RIGHT(A4,4) -> 0003 | K4: =VLOOKUP(D4,客户信息表!$A$3:$H$23,5,0) -> A | L4: 陈静 | M4: 华南 | N4: =SUBSTITUTE(TRIM(M4),"区","") -> 华南 | O4: CP003 | P4: 碎纸机 SafeCut S8 | Q4: 899 | R4: 1 | S4: =IF(ISBLANK(R4),U4/Q4,VALUE(R4)) -> 1 | T4: =VLOOKUP(S4,折扣阶梯!$A$3:$C$7,2,TRUE) -> 1 | U4: 899 | V4: =IF(Q4*S4=VALUE(SUBSTITUTE(U4,"¥","")),VALUE(SUBSTITUTE(U4,"¥","")),Q4*S4) -> 899 | W4: 已发货 | X4: =V4*T4 -> 899 | Y4: =_xlfn.XLOOKUP(O4,产品信息表!$A$4:$A$15,产品信息表!$E$4:$E$15) -> 620 | Z4: =(X4-Y4*S4)/X4 -> 0.31034483 | AA4: =_xlfn.RANK.EQ(V4,V4:V205,0) -> 193
A5: DD-20260107-0004 | B5: 2026年1月7日 | C5: =TEXT(SUBSTITUTE(B5,".","/"),"yyyy-mm-dd") -> 2026-01-07 | D5: KH012 | E5: =VLOOKUP(D5,客户信息表!A$3:H$23,2,0) -> 长沙麓山科技 | F5: 长沙麓山科技 | G5: =INDEX(客户信息表!$A$4:$H$23,MATCH(F5,客户信息表!$B$4:$B$23,0),1) -> KH012 | H5: =_xlfn.XLOOKUP(O5,产品信息表!$A$4:$A$15,产品信息表!$C$4:$C$15) -> 办公设备 | I5: =DATE(MID(A5,4,4),MID(A5,8,2),MID(A5,10,2)) -> 46029 | J5: =RIGHT(A5,4) -> 0004 | K5: =VLOOKUP(D5,客户信息表!$A$3:$H$23,5,0) -> B | L5: 孙悦 | M5: 华中区 | N5: =SUBSTITUTE(TRIM(M5),"区","") -> 华中 | O5: CP003 | P5: 碎纸机 SafeCut S8 | Q5: 899 | R5: 6 | S5: =IF(ISBLANK(R5),U5/Q5,VALUE(R5)) -> 6 | T5: =VLOOKUP(S5,折扣阶梯!$A$3:$C$7,2,TRUE) -> 1 | U5: 5394 | V5: =IF(Q5*S5=VALUE(SUBSTITUTE(U5,"¥","")),VALUE(SUBSTITUTE(U5,"¥","")),Q5*S5) -> 5394 | W5: 已发货 | X5: =V5*T5 -> 5394 | Y5: =_xlfn.XLOOKUP(O5,产品信息表!$A$4:$A$15,产品信息表!$E$4:$E$15) -> 620 | Z5: =(X5-Y5*S5)/X5 -> 0.31034483 | AA5: =_xlfn.RANK.EQ(V5,V5:V206,0) -> 138
A6: DD-20260107-0005 | B6: 46029 | C6: =TEXT(SUBSTITUTE(B6,".","/"),"yyyy-mm-dd") -> 2026-01-07 | D6: KH019 | E6: =VLOOKUP(D6,客户信息表!A$3:H$23,2,0) -> 北京中关新材 | F6: 北京中关新材 | G6: =INDEX(客户信息表!$A$4:$H$23,MATCH(F6,客户信息表!$B$4:$B$23,0),1) -> KH019 | H6: =_xlfn.XLOOKUP(O6,产品信息表!$A$4:$A$15,产品信息表!$C$4:$C$15) -> 办公耗材 | I6: =DATE(MID(A6,4,4),MID(A6,8,2),MID(A6,10,2)) -> 46029 | J6: =RIGHT(A6,4) -> 0005 | K6: =VLOOKUP(D6,客户信息表!$A$3:$H$23,5,0) -> B | L6: 王强 | M6: 华北 | N6: =SUBSTITUTE(TRIM(M6),"区","") -> 华北 | O6: CP008 | P6: A4复印纸（5包/箱） | Q6: 128 | R6: 70 | S6: =IF(ISBLANK(R6),U6/Q6,VALUE(R6)) -> 70 | T6: =VLOOKUP(S6,折扣阶梯!$A$3:$C$7,2,TRUE) -> 0.9 | U6: 8960 | V6: =IF(Q6*S6=VALUE(SUBSTITUTE(U6,"¥","")),VALUE(SUBSTITUTE(U6,"¥","")),Q6*S6) -> 8960 | W6: 已取消 | X6: =V6*T6 -> 8064 | Y6: =_xlfn.XLOOKUP(O6,产品信息表!$A$4:$A$15,产品信息表!$E$4:$E$15) -> 95 | Z6: =(X6-Y6*S6)/X6 -> 0.17534722 | AA6: =_xlfn.RANK.EQ(V6,V6:V207,0) -> 110
A7: DD-20260109-0006 | B7: 46031 | C7: =TEXT(SUBSTITUTE(B7,".","/"),"yyyy-mm-dd") -> 2026-01-09 | D7: KH017 | E7: =VLOOKUP(D7,客户信息表!A$3:H$23,2,0) -> 郑州中原物流 | F7: 郑州中原物流 | G7: =INDEX(客户信息表!$A$4:$H$23,MATCH(F7,客户信息表!$B$4:$B$23,0),1) -> KH017 | H7: =_xlfn.XLOOKUP(O7,产品信息表!$A$4:$A$15,产品信息表!$C$4:$C$15) -> 办公耗材 | I7: =DATE(MID(A7,4,4),MID(A7,8,2),MID(A7,10,2)) -> 46031 | J7: =RIGHT(A7,4) -> 0006 | K7: =VLOOKUP(D7,客户信息表!$A$3:$H$23,5,0) -> B | L7: 赵磊 | M7: 华中 | N7: =SUBSTITUTE(TRIM(M7),"区","") -> 华中 | O7: CP008 | P7: A4复印纸（5包/箱） | Q7: 128 | R7: 20 | S7: =IF(ISBLANK(R7),U7/Q7,VALUE(R7)) -> 20 | T7: =VLOOKUP(S7,折扣阶梯!$A$3:$C$7,2,TRUE) -> 0.95 | U7: 2560 | V7: =IF(Q7*S7=VALUE(SUBSTITUTE(U7,"¥","")),VALUE(SUBSTITUTE(U7,"¥","")),Q7*S7) -> 2560 | W7: 已发货 | X7: =V7*T7 -> 2432 | Y7: =_xlfn.XLOOKUP(O7,产品信息表!$A$4:$A$15,产品信息表!$E$4:$E$15) -> 95 | Z7: =(X7-Y7*S7)/X7 -> 0.21875 | AA7: =_xlfn.RANK.EQ(V7,V7:V208,0) -> 176
A8: DD-20260109-0007 | B8: 46031 | C8: =TEXT(SUBSTITUTE(B8,".","/"),"yyyy-mm-dd") -> 2026-01-09 | D8: KH019 | E8: =VLOOKUP(D8,客户信息表!A$3:H$23,2,0) -> 北京中关新材 | F8: 北京中关新材 | G8: =INDEX(客户信息表!$A$4:$H$23,MATCH(F8,客户信息表!$B$4:$B$23,0),1) -> KH019 | H8: =_xlfn.XLOOKUP(O8,产品信息表!$A$4:$A$15,产品信息表!$C$4:$C$15) -> 办公耗材 | I8: =DATE(MID(A8,4,4),MID(A8,8,2),MID(A8,10,2)) -> 46031 | J8: =RIGHT(A8,4) -> 0007 | K8: =VLOOKUP(D8,客户信息表!$A$3:$H$23,5,0) -> B | L8: 陈静 | M8: 华北 | N8: =SUBSTITUTE(TRIM(M8),"区","") -> 华北 | O8: CP010 | P8: 签字笔盒装（12支） | Q8: 45 | R8: 85 | S8: =IF(ISBLANK(R8),U8/Q8,VALUE(R8)) -> 85 | T8: =VLOOKUP(S8,折扣阶梯!$A$3:$C$7,2,TRUE) -> 0.9 | U8: 3825 | V8: =IF(Q8*S8=VALUE(SUBSTITUTE(U8,"¥","")),VALUE(SUBSTITUTE(U8,"¥","")),Q8*S8) -> 3825 | W8: 已完成 | X8: =V8*T8 -> 3442.5 | Y8: =_xlfn.XLOOKUP(O8,产品信息表!$A$4:$A$15,产品信息表!$E$4:$E$15) -> 28 | Z8: =(X8-Y8*S8)/X8 -> 0.30864198 | AA8: =_xlfn.RANK.EQ(V8,V8:V209,0) -> 152
A9: DD-20260113-0008 | B9: 46035 | C9: =TEXT(SUBSTITUTE(B9,".","/"),"yyyy-mm-dd") -> 2026-01-13 | D9: KH007 | E9: =VLOOKUP(D9,客户信息表!A$3:H$23,2,0) -> 武汉长江实业 | F9: 武汉长江实业 | G9: =INDEX(客户信息表!$A$4:$H$23,MATCH(F9,客户信息表!$B$4:$B$23,0),1) -> KH007 | H9: =_xlfn.XLOOKUP(O9,产品信息表!$A$4:$A$15,产品信息表!$C$4:$C$15) -> 办公设备 | I9: =DATE(MID(A9,4,4),MID(A9,8,2),MID(A9,10,2)) -> 46035 | J9: =RIGHT(A9,4) -> 0008 | K9: =VLOOKUP(D9,客户信息表!$A$3:$H$23,5,0) -> B | L9: 赵磊 | M9: 华中 | N9: =SUBSTITUTE(TRIM(M9),"区","") -> 华中 | O9: CP003 | P9: 碎纸机 SafeCut S8 | Q9: 899 | R9: 4 | S9: =IF(ISBLANK(R9),U9/Q9,VALUE(R9)) -> 4 | T9: =VLOOKUP(S9,折扣阶梯!$A$3:$C$7,2,TRUE) -> 1 | U9: 3596 | V9: =IF(Q9*S9=VALUE(SUBSTITUTE(U9,"¥","")),VALUE(SUBSTITUTE(U9,"¥","")),Q9*S9) -> 3596 | W9: 已完成 | X9: =V9*T9 -> 3596 | Y9: =_xlfn.XLOOKUP(O9,产品信息表!$A$4:$A$15,产品信息表!$E$4:$E$15) -> 620 | Z9: =(X9-Y9*S9)/X9 -> 0.31034483 | AA9: =_xlfn.RANK.EQ(V9,V9:V210,0) -> 154
A10: DD-20260117-0009 | B10: 46039 | C10: =TEXT(SUBSTITUTE(B10,".","/"),"yyyy-mm-dd") -> 2026-01-17 | D10: KH002 | E10: =VLOOKUP(D10,客户信息表!A$3:H$23,2,0) -> 上海锦程贸易 | F10: 上海锦程贸易 | G10: =INDEX(客户信息表!$A$4:$H$23,MATCH(F10,客户信息表!$B$4:$B$23,0),1) -> KH002 | H10: =_xlfn.XLOOKUP(O10,产品信息表!$A$4:$A$15,产品信息表!$C$4:$C$15) -> 软件服务 | I10: =DATE(MID(A10,4,4),MID(A10,8,2),MID(A10,10,2)) -> 46039 | J10: =RIGHT(A10,4) -> 0009 | K10: =VLOOKUP(D10,客户信息表!$A$3:$H$23,5,0) -> B | L10: 杨帆 | M10: 华东 | N10: =SUBSTITUTE(TRIM(M10),"区","") -> 华东 | O10: CP011 | P10: 办公软件年费授权 | Q10: 699 | R10: 5 | S10: =IF(ISBLANK(R10),U10/Q10,VALUE(R10)) -> 5 | T10: =VLOOKUP(S10,折扣阶梯!$A$3:$C$7,2,TRUE) -> 1 | U10: 3495 | V10: =IF(Q10*S10=VALUE(SUBSTITUTE(U10,"¥","")),VALUE(SUBSTITUTE(U10,"¥","")),Q10*S10) -> 3495 | W10: 已发货 | X10: =V10*T10 -> 3495 | Y10: =_xlfn.XLOOKUP(O10,产品信息表!$A$4:$A$15,产品信息表!$E$4:$E$15) -> 300 | Z10: =(X10-Y10*S10)/X10 -> 0.57081545 | AA10: =_xlfn.RANK.EQ(V10,V10:V211,0) -> 159
A11: DD-20260120-0010 | B11: 46042 | C11: =TEXT(SUBSTITUTE(B11,".","/"),"yyyy-mm-dd") -> 2026-01-20 | D11: KH019 | E11: =VLOOKUP(D11,客户信息表!A$3:H$23,2,0) -> 北京中关新材 | F11: 北京中关新材 | G11: =INDEX(客户信息表!$A$4:$H$23,MATCH(F11,客户信息表!$B$4:$B$23,0),1) -> KH019 | H11: =_xlfn.XLOOKUP(O11,产品信息表!$A$4:$A$15,产品信息表!$C$4:$C$15) -> 软件服务 | I11: =DATE(MID(A11,4,4),MID(A11,8,2),MID(A11,10,2)) -> 46042 | J11: =RIGHT(A11,4) -> 0010 | K11: =VLOOKUP(D11,客户信息表!$A$3:$H$23,5,0) -> B | L11: 孙悦 | M11: 华北 | N11: =SUBSTITUTE(TRIM(M11),"区","") -> 华北 | O11: CP012 | P11: 云存储服务（1TB/年） | Q11: 599 | R11: 3 | S11: =IF(ISBLANK(R11),U11/Q11,VALUE(R11)) -> 3 | T11: =VLOOKUP(S11,折扣阶梯!$A$3:$C$7,2,TRUE) -> 1 | U11: 1797 | V11: =IF(Q11*S11=VALUE(SUBSTITUTE(U11,"¥","")),VALUE(SUBSTITUTE(U11,"¥","")),Q11*S11) -> 1797 | W11: 已完成 | X11: =V11*T11 -> 1797 | Y11: =_xlfn.XLOOKUP(O11,产品信息表!$A$4:$A$15,产品信息表!$E$4:$E$15) -> 250 | Z11: =(X11-Y11*S11)/X11 -> 0.58263773 | AA11: =_xlfn.RANK.EQ(V11,V11:V212,0) -> 176
A12: DD-20260121-0011 | B12: 46043 | C12: =TEXT(SUBSTITUTE(B12,".","/"),"yyyy-mm-dd") -> 2026-01-21 | D12: KH005 | E12: =VLOOKUP(D12,客户信息表!A$3:H$23,2,0) -> 杭州云图信息 | F12: 杭州云图信息 | G12: =INDEX(客户信息表!$A$4:$H$23,MATCH(F12,客户信息表!$B$4:$B$23,0),1) -> KH005 | H12: =_xlfn.XLOOKUP(O12,产品信息表!$A$4:$A$15,产品信息表!$C$4:$C$15) -> 电子数码 | I12: =DATE(MID(A12,4,4),MID(A12,8,2),MID(A12,10,2)) -> 46043 | J12: =RIGHT(A12,4) -> 0011 | K12: =VLOOKUP(D12,客户信息表!$A$3:$H$23,5,0) -> A | L12: 孙悦 | M12: 华东 | N12: =SUBSTITUTE(TRIM(M12),"区","") -> 华东 | O12: CP006 | P12: 显示器 ViewMax 27 | Q12: 1299 | R12: 2 | S12: =IF(ISBLANK(R12),U12/Q12,VALUE(R12)) -> 2 | T12: =VLOOKUP(S12,折扣阶梯!$A$3:$C$7,2,TRUE) -> 1 | U12: 2598 | V12: =IF(Q12*S12=VALUE(SUBSTITUTE(U12,"¥","")),VALUE(SUBSTITUTE(U12,"¥","")),Q12*S12) -> 2598 | W12: 已取消 | X12: =V12*T12 -> 2598 | Y12: =_xlfn.XLOOKUP(O12,产品信息表!$A$4:$A$15,产品信息表!$E$4:$E$15) -> 950 | Z12: =(X12-Y12*S12)/X12 -> 0.26866821 | AA12: =_xlfn.RANK.EQ(V12,V12:V213,0) -> 171
A13: DD-20260123-0012 | B13: 46045 | C13: =TEXT(SUBSTITUTE(B13,".","/"),"yyyy-mm-dd") -> 2026-01-23 | D13: KH011 | E13: =VLOOKUP(D13,客户信息表!A$3:H$23,2,0) -> 重庆山城办公设备 | F13: 重庆山城办公设备 | G13: =INDEX(客户信息表!$A$4:$H$23,MATCH(F13,客户信息表!$B$4:$B$23,0),1) -> KH011 | H13: =_xlfn.XLOOKUP(O13,产品信息表!$A$4:$A$15,产品信息表!$C$4:$C$15) -> 软件服务 | I13: =DATE(MID(A13,4,4),MID(A13,8,2),MID(A13,10,2)) -> 46045 | J13: =RIGHT(A13,4) -> 0012 | K13: =VLOOKUP(D13,客户信息表!$A$3:$H$23,5,0) -> B | L13: 刘洋 | M13: 西南 | N13: =SUBSTITUTE(TRIM(M13),"区","") -> 西南 | O13: CP011 | P13: 办公软件年费授权 | Q13: 699 | R13: 11 | S13: =IF(ISBLANK(R13),U13/Q13,VALUE(R13)) -> 11 | T13: =VLOOKUP(S13,折扣阶梯!$A$3:$C$7,2,TRUE) -> 0.95 | U13: 7689 | V13: =IF(Q13*S13=VALUE(SUBSTITUTE(U13,"¥","")),VALUE(SUBSTITUTE(U13,"¥","")),Q13*S13) -> 7689 | W13: 已完成 | X13: =V13*T13 -> 7304.55 | Y13: =_xlfn.XLOOKUP(O13,产品信息表!$A$4:$A$15,产品信息表!$E$4:$E$15) -> 300 | Z13: =(X13-Y13*S13)/X13 -> 0.54822679 | AA13: =_xlfn.RANK.EQ(V13,V13:V214,0) -> 116
A14: DD-20260124-0013 | B14: 46046 | C14: =TEXT(SUBSTITUTE(B14,".","/"),"yyyy-mm-dd") -> 2026-01-24 | D14: KH006 | E14: =VLOOKUP(D14,客户信息表!A$3:H$23,2,0) -> 成都天府商贸 | F14: 成都天府商贸 | G14: =INDEX(客户信息表!$A$4:$H$23,MATCH(F14,客户信息表!$B$4:$B$23,0),1) -> KH006 | H14: =_xlfn.XLOOKUP(O14,产品信息表!$A$4:$A$15,产品信息表!$C$4:$C$15) -> 办公耗材 | I14: =DATE(MID(A14,4,4),MID(A14,8,2),MID(A14,10,2)) -> 46046 | J14: =RIGHT(A14,4) -> 0013 | K14: =VLOOKUP(D14,客户信息表!$A$3:$H$23,5,0) -> C | L14: 李娜 | M14: 西南 | N14: =SUBSTITUTE(TRIM(M14),"区","") -> 西南 | O14: CP009 | P14: 激光硒鼓 TonerMax 12A | Q14: 385 | R14: 96 | S14: =IF(ISBLANK(R14),U14/Q14,VALUE(R14)) -> 96 | T14: =VLOOKUP(S14,折扣阶梯!$A$3:$C$7,2,TRUE) -> 0.9 | U14: 36960 | V14: =IF(Q14*S14=VALUE(SUBSTITUTE(U14,"¥","")),VALUE(SUBSTITUTE(U14,"¥","")),Q14*S14) -> 36960 | W14: 已完成 | X14: =V14*T14 -> 33264 | Y14: =_xlfn.XLOOKUP(O14,产品信息表!$A$4:$A$15,产品信息表!$E$4:$E$15) -> 260 | Z14: =(X14-Y14*S14)/X14 -> 0.24963925 | AA14: =_xlfn.RANK.EQ(V14,V14:V215,0) -> 18
A15: DD-20260125-0014 | B15: 46047 | C15: =TEXT(SUBSTITUTE(B15,".","/"),"yyyy-mm-dd") -> 2026-01-25 | D15: KH001 | E15: =VLOOKUP(D15,客户信息表!A$3:H$23,2,0) -> 北京华信科技 | F15: 北京华信科技 | G15: =INDEX(客户信息表!$A$4:$H$23,MATCH(F15,客户信息表!$B$4:$B$23,0),1) -> KH001 | H15: =_xlfn.XLOOKUP(O15,产品信息表!$A$4:$A$15,产品信息表!$C$4:$C$15) -> 办公耗材 | I15: =DATE(MID(A15,4,4),MID(A15,8,2),MID(A15,10,2)) -> 46047 | J15: =RIGHT(A15,4) -> 0014 | K15: =VLOOKUP(D15,客户信息表!$A$3:$H$23,5,0) -> A | L15: 张伟 | M15: 华北 | N15: =SUBSTITUTE(TRIM(M15),"区","") -> 华北 | O15: CP009 | P15: 激光硒鼓 TonerMax 12A | Q15: 385 | R15: 32 | S15: =IF(ISBLANK(R15),U15/Q15,VALUE(R15)) -> 32 | T15: =VLOOKUP(S15,折扣阶梯!$A$3:$C$7,2,TRUE) -> 0.95 | U15: 12320 | V15: =IF(Q15*S15=VALUE(SUBSTITUTE(U15,"¥","")),VALUE(SUBSTITUTE(U15,"¥","")),Q15*S15) -> 12320 | W15: 已发货 | X15: =V15*T15 -> 11704 | Y15: =_xlfn.XLOOKUP(O15,产品信息表!$A$4:$A$15,产品信息表!$E$4:$E$15) -> 260 | Z15: =(X15-Y15*S15)/X15 -> 0.28913192 | AA15: =_xlfn.RANK.EQ(V15,V15:V216,0) -> 89
A16: DD-20260126-0015 | B16: 46048 | C16: =TEXT(SUBSTITUTE(B16,".","/"),"yyyy-mm-dd") -> 2026-01-26 | D16: KH019 | E16: =VLOOKUP(D16,客户信息表!A$3:H$23,2,0) -> 北京中关新材 | F16: 北京中关新材 | G16: =INDEX(客户信息表!$A$4:$H$23,MATCH(F16,客户信息表!$B$4:$B$23,0),1) -> KH019 | H16: =_xlfn.XLOOKUP(O16,产品信息表!$A$4:$A$15,产品信息表!$C$4:$C$15) -> 办公设备 | I16: =DATE(MID(A16,4,4),MID(A16,8,2),MID(A16,10,2)) -> 46048 | J16: =RIGHT(A16,4) -> 0015 | K16: =VLOOKUP(D16,客户信息表!$A$3:$H$23,5,0) -> B | L16: 孙悦 | M16: 华北 | N16: =SUBSTITUTE(TRIM(M16),"区","") -> 华北 | O16: CP001 | P16: 激光打印机 ProLaser 200 | Q16: 2499 | S16: =IF(ISBLANK(R16),U16/Q16,VALUE(R16)) -> 4 | T16: =VLOOKUP(S16,折扣阶梯!$A$3:$C$7,2,TRUE) -> 1 | U16: 9996 | V16: =IF(Q16*S16=VALUE(SUBSTITUTE(U16,"¥","")),VALUE(SUBSTITUTE(U16,"¥","")),Q16*S16) -> 9996 | W16: 已发货 | X16: =V16*T16 -> 9996 | Y16: =_xlfn.XLOOKUP(O16,产品信息表!$A$4:$A$15,产品信息表!$E$4:$E$15) -> 1850 | Z16: =(X16-Y16*S16)/X16 -> 0.25970388 | AA16: =_xlfn.RANK.EQ(V16,V16:V217,0) -> 100
A17: DD-20260816-0196 | B17: 46250 | C17: =TEXT(SUBSTITUTE(B17,".","/"),"yyyy-mm-dd") -> 2026-08-16 | D17: KH016 | E17: =VLOOKUP(D17,客户信息表!A$3:H$23,2,0) -> 昆明滇池科技 | F17: 昆明滇池科技 | G17: =INDEX(客户信息表!$A$4:$H$23,MATCH(F17,客户信息表!$B$4:$B$23,0),1) -> KH016 | H17: =_xlfn.XLOOKUP(O17,产品信息表!$A$4:$A$15,产品信息表!$C$4:$C$15) -> 办公耗材 | I17: =DATE(MID(A17,4,4),MID(A17,8,2),MID(A17,10,2)) -> 46250 | J17: =RIGHT(A17,4) -> 0196 | K17: =VLOOKUP(D17,客户信息表!$A$3:$H$23,5,0) -> C | L17: 赵磊 | M17: 西南区 | N17: =SUBSTITUTE(TRIM(M17),"区","") -> 西南 | O17: CP008 | P17: A4复印纸（5包/箱） | Q17: 128 | R17: 77 | S17: =IF(ISBLANK(R17),U17/Q17,VALUE(R17)) -> 77 | T17: =VLOOKUP(S17,折扣阶梯!$A$3:$C$7,2,TRUE) -> 0.9 | U17: 9856 | V17: =IF(Q17*S17=VALUE(SUBSTITUTE(U17,"¥","")),VALUE(SUBSTITUTE(U17,"¥","")),Q17*S17) -> 9856 | W17: 已完成 | X17: =V17*T17 -> 8870.4 | Y17: =_xlfn.XLOOKUP(O17,产品信息表!$A$4:$A$15,产品信息表!$E$4:$E$15) -> 95 | Z17: =(X17-Y17*S17)/X17 -> 0.17534722 | AA17: =_xlfn.RANK.EQ(V17,V17:V218,0) -> 102
A18: DD-20260126-0016 | B18: 46048 | C18: =TEXT(SUBSTITUTE(B18,".","/"),"yyyy-mm-dd") -> 2026-01-26 | D18: KH017 | E18: =VLOOKUP(D18,客户信息表!A$3:H$23,2,0) -> 郑州中原物流 | F18: 郑州中原物流 | G18: =INDEX(客户信息表!$A$4:$H$23,MATCH(F18,客户信息表!$B$4:$B$23,0),1) -> KH017 | H18: =_xlfn.XLOOKUP(O18,产品信息表!$A$4:$A$15,产品信息表!$C$4:$C$15) -> 办公设备 | I18: =DATE(MID(A18,4,4),MID(A18,8,2),MID(A18,10,2)) -> 46048 | J18: =RIGHT(A18,4) -> 0016 | K18: =VLOOKUP(D18,客户信息表!$A$3:$H$23,5,0) -> B | L18: 王强 | M18: 华中区 | N18: =SUBSTITUTE(TRIM(M18),"区","") -> 华中 | O18: CP003 | P18: 碎纸机 SafeCut S8 | Q18: 899 | R18: 4 | S18: =IF(ISBLANK(R18),U18/Q18,VALUE(R18)) -> 4 | T18: =VLOOKUP(S18,折扣阶梯!$A$3:$C$7,2,TRUE) -> 1 | U18: 3596 | V18: =IF(Q18*S18=VALUE(SUBSTITUTE(U18,"¥","")),VALUE(SUBSTITUTE(U18,"¥","")),Q18*S18) -> 3596 | W18: 已完成 | X18: =V18*T18 -> 3596 | Y18: =_xlfn.XLOOKUP(O18,产品信息表!$A$4:$A$15,产品信息表!$E$4:$E$15) -> 620 | Z18: =(X18-Y18*S18)/X18 -> 0.31034483 | AA18: =_xlfn.RANK.EQ(V18,V18:V219,0) -> 149
A19: DD-20260127-0017 | B19: 46049 | C19: =TEXT(SUBSTITUTE(B19,".","/"),"yyyy-mm-dd") -> 2026-01-27 | D19: KH017 | E19: =VLOOKUP(D19,客户信息表!A$3:H$23,2,0) -> 郑州中原物流 | F19: 郑州中原物流 | G19: =INDEX(客户信息表!$A$4:$H$23,MATCH(F19,客户信息表!$B$4:$B$23,0),1) -> KH017 | H19: =_xlfn.XLOOKUP(O19,产品信息表!$A$4:$A$15,产品信息表!$C$4:$C$15) -> 电子数码 | I19: =DATE(MID(A19,4,4),MID(A19,8,2),MID(A19,10,2)) -> 46049 | J19: =RIGHT(A19,4) -> 0017 | K19: =VLOOKUP(D19,客户信息表!$A$3:$H$23,5,0) -> B | L19: 赵磊 | M19: 华中 | N19: =SUBSTITUTE(TRIM(M19),"区","") -> 华中 | O19: CP007 | P19: 无线键鼠套装 KeyFree 2.0 | Q19: 299 | R19: 7 | S19: =IF(ISBLANK(R19),U19/Q19,VALUE(R19)) -> 7 | T19: =VLOOKUP(S19,折扣阶梯!$A$3:$C$7,2,TRUE) -> 1 | U19: 2093 | V19: =IF(Q19*S19=VALUE(SUBSTITUTE(U19,"¥","")),VALUE(SUBSTITUTE(U19,"¥","")),Q19*S19) -> 2093 | W19: 待付款 | X19: =V19*T19 -> 2093 | Y19: =_xlfn.XLOOKUP(O19,产品信息表!$A$4:$A$15,产品信息表!$E$4:$E$15) -> 190 | Z19: =(X19-Y19*S19)/X19 -> 0.36454849 | AA19: =_xlfn.RANK.EQ(V19,V19:V220,0) -> 167
A20: DD-20260127-0018 | B20: 46049 | C20: =TEXT(SUBSTITUTE(B20,".","/"),"yyyy-mm-dd") -> 2026-01-27 | D20: KH007 | E20: =VLOOKUP(D20,客户信息表!A$3:H$23,2,0) -> 武汉长江实业 | F20: 武汉长江实业 | G20: =INDEX(客户信息表!$A$4:$H$23,MATCH(F20,客户信息表!$B$4:$B$23,0),1) -> KH007 | H20: =_xlfn.XLOOKUP(O20,产品信息表!$A$4:$A$15,产品信息表!$C$4:$C$15) -> 电子数码 | I20: =DATE(MID(A20,4,4),MID(A20,8,2),MID(A20,10,2)) -> 46049 | J20: =RIGHT(A20,4) -> 0018 | K20: =VLOOKUP(D20,客户信息表!$A$3:$H$23,5,0) -> B | L20: 陈静 | M20: 华中 | N20: =SUBSTITUTE(TRIM(M20),"区","") -> 华中 | O20: CP004 | P20: 笔记本电脑 TechBook 14 | Q20: 5699 | R20: 3 | S20: =IF(ISBLANK(R20),U20/Q20,VALUE(R20)) -> 3 | T20: =VLOOKUP(S20,折扣阶梯!$A$3:$C$7,2,TRUE) -> 1 | U20: 17097 | V20: =IF(Q20*S20=VALUE(SUBSTITUTE(U20,"¥","")),VALUE(SUBSTITUTE(U20,"¥","")),Q20*S20) -> 17097 | W20: 已完成 | X20: =V20*T20 -> 17097 | Y20: =_xlfn.XLOOKUP(O20,产品信息表!$A$4:$A$15,产品信息表!$E$4:$E$15) -> 4800 | Z20: =(X20-Y20*S20)/X20 -> 0.15774697 | AA20: =_xlfn.RANK.EQ(V20,V20:V221,0) -> 63
A21: DD-20260129-0019 | B21: 46051 | C21: =TEXT(SUBSTITUTE(B21,".","/"),"yyyy-mm-dd") -> 2026-01-29 | D21: KH020 | E21: =VLOOKUP(D21,客户信息表!A$3:H$23,2,0) -> 合肥科大国创 | F21: 合肥科大国创 | G21: =INDEX(客户信息表!$A$4:$H$23,MATCH(F21,客户信息表!$B$4:$B$23,0),1) -> KH020 | H21: =_xlfn.XLOOKUP(O21,产品信息表!$A$4:$A$15,产品信息表!$C$4:$C$15) -> 软件服务 | I21: =DATE(MID(A21,4,4),MID(A21,8,2),MID(A21,10,2)) -> 46051 | J21: =RIGHT(A21,4) -> 0019 | K21: =VLOOKUP(D21,客户信息表!$A$3:$H$23,5,0) -> C | L21: 孙悦 | M21: 华东 | N21: =SUBSTITUTE(TRIM(M21),"区","") -> 华东 | O21: CP011 | P21: 办公软件年费授权 | Q21: 699 | R21: 20 | S21: =IF(ISBLANK(R21),U21/Q21,VALUE(R21)) -> 20 | T21: =VLOOKUP(S21,折扣阶梯!$A$3:$C$7,2,TRUE) -> 0.95 | U21: 13980 | V21: =IF(Q21*S21=VALUE(SUBSTITUTE(U21,"¥","")),VALUE(SUBSTITUTE(U21,"¥","")),Q21*S21) -> 13980 | W21: 已完成 | X21: =V21*T21 -> 13281 | Y21: =_xlfn.XLOOKUP(O21,产品信息表!$A$4:$A$15,产品信息表!$E$4:$E$15) -> 300 | Z21: =(X21-Y21*S21)/X21 -> 0.54822679 | AA21: =_xlfn.RANK.EQ(V21,V21:V222,0) -> 78
A22: DD-20260130-0020 | B22: 46052 | C22: =TEXT(SUBSTITUTE(B22,".","/"),"yyyy-mm-dd") -> 2026-01-30 | D22: KH010 | E22: =VLOOKUP(D22,客户信息表!A$3:H$23,2,0) -> 苏州创智科技 | F22: 苏州创智科技 | G22: =INDEX(客户信息表!$A$4:$H$23,MATCH(F22,客户信息表!$B$4:$B$23,0),1) -> KH010 | H22: =_xlfn.XLOOKUP(O22,产品信息表!$A$4:$A$15,产品信息表!$C$4:$C$15) -> 电子数码 | I22: =DATE(MID(A22,4,4),MID(A22,8,2),MID(A22,10,2)) -> 46052 | J22: =RIGHT(A22,4) -> 0020 | K22: =VLOOKUP(D22,客户信息表!$A$3:$H$23,5,0) -> A | L22: 陈静 | M22: 华东 | N22: =SUBSTITUTE(TRIM(M22),"区","") -> 华东 | O22: CP007 | P22: 无线键鼠套装 KeyFree 2.0 | Q22: 299 | R22: 9 | S22: =IF(ISBLANK(R22),U22/Q22,VALUE(R22)) -> 9 | T22: =VLOOKUP(S22,折扣阶梯!$A$3:$C$7,2,TRUE) -> 1 | U22: ¥2,691.00 | V22: =IF(Q22*S22=VALUE(SUBSTITUTE(U22,"¥","")),VALUE(SUBSTITUTE(U22,"¥","")),Q22*S22) -> 2691 | W22: 待付款 | X22: =V22*T22 -> 2691 | Y22: =_xlfn.XLOOKUP(O22,产品信息表!$A$4:$A$15,产品信息表!$E$4:$E$15) -> 190 | Z22: =(X22-Y22*S22)/X22 -> 0.36454849 | AA22: =_xlfn.RANK.EQ(V22,V22:V223,0) -> 161
A23: DD-20260131-0021 | B23: 46053 | C23: =TEXT(SUBSTITUTE(B23,".","/"),"yyyy-mm-dd") -> 2026-01-31 | D23: KH017 | E23: =VLOOKUP(D23,客户信息表!A$3:H$23,2,0) -> 郑州中原物流 | F23: 郑州中原物流 | G23: =INDEX(客户信息表!$A$4:$H$23,MATCH(F23,客户信息表!$B$4:$B$23,0),1) -> KH017 | H23: =_xlfn.XLOOKUP(O23,产品信息表!$A$4:$A$15,产品信息表!$C$4:$C$15) -> 电子数码 | I23: =DATE(MID(A23,4,4),MID(A23,8,2),MID(A23,10,2)) -> 46053 | J23: =RIGHT(A23,4) -> 0021 | K23: =VLOOKUP(D23,客户信息表!$A$3:$H$23,5,0) -> B | L23: 孙悦 | M23: 华中 | N23: =SUBSTITUTE(TRIM(M23),"区","") -> 华中 | O23: CP004 | P23: 笔记本电脑 TechBook 14 | Q23: 5699 | R23: 2 | S23: =IF(ISBLANK(R23),U23/Q23,VALUE(R23)) -> 2 | T23: =VLOOKUP(S23,折扣阶梯!$A$3:$C$7,2,TRUE) -> 1 | U23: 11398 | V23: =IF(Q23*S23=VALUE(SUBSTITUTE(U23,"¥","")),VALUE(SUBSTITUTE(U23,"¥","")),Q23*S23) -> 11398 | W23: 已发货 | X23: =V23*T23 -> 11398 | Y23: =_xlfn.XLOOKUP(O23,产品信息表!$A$4:$A$15,产品信息表!$E$4:$E$15) -> 4800 | Z23: =(X23-Y23*S23)/X23 -> 0.15774697 | AA23: =_xlfn.RANK.EQ(V23,V23:V224,0) -> 92
A24: DD-20260201-0022 | B24: 46054 | C24: =TEXT(SUBSTITUTE(B24,".","/"),"yyyy-mm-dd") -> 2026-02-01 | D24: KH007 | E24: =VLOOKUP(D24,客户信息表!A$3:H$23,2,0) -> 武汉长江实业 | F24: 武汉长江实业 | G24: =INDEX(客户信息表!$A$4:$H$23,MATCH(F24,客户信息表!$B$4:$B$23,0),1) -> KH007 | H24: =_xlfn.XLOOKUP(O24,产品信息表!$A$4:$A$15,产品信息表!$C$4:$C$15) -> 办公耗材 | I24: =DATE(MID(A24,4,4),MID(A24,8,2),MID(A24,10,2)) -> 46054 | J24: =RIGHT(A24,4) -> 0022 | K24: =VLOOKUP(D24,客户信息表!$A$3:$H$23,5,0) -> B | L24: 王强 | M24: 华中 | N24: =SUBSTITUTE(TRIM(M24),"区","") -> 华中 | O24: CP010 | P24: 签字笔盒装（12支） | Q24: 45 | R24: 118 | S24: =IF(ISBLANK(R24),U24/Q24,VALUE(R24)) -> 118 | T24: =VLOOKUP(S24,折扣阶梯!$A$3:$C$7,2,TRUE) -> 0.85 | U24: 5310 | V24: =IF(Q24*S24=VALUE(SUBSTITUTE(U24,"¥","")),VALUE(SUBSTITUTE(U24,"¥","")),Q24*S24) -> 5310 | W24: 已取消 | X24: =V24*T24 -> 4513.5 | Y24: =_xlfn.XLOOKUP(O24,产品信息表!$A$4:$A$15,产品信息表!$E$4:$E$15) -> 28 | Z24: =(X24-Y24*S24)/X24 -> 0.26797386 | AA24: =_xlfn.RANK.EQ(V24,V24:V225,0) -> 129
A25: DD-20260203-0023 | B25: 46056 | C25: =TEXT(SUBSTITUTE(B25,".","/"),"yyyy-mm-dd") -> 2026-02-03 | D25: KH006 | E25: =VLOOKUP(D25,客户信息表!A$3:H$23,2,0) -> 成都天府商贸 | F25: 成都天府商贸 | G25: =INDEX(客户信息表!$A$4:$H$23,MATCH(F25,客户信息表!$B$4:$B$23,0),1) -> KH006 | H25: =_xlfn.XLOOKUP(O25,产品信息表!$A$4:$A$15,产品信息表!$C$4:$C$15) -> 办公设备 | I25: =DATE(MID(A25,4,4),MID(A25,8,2),MID(A25,10,2)) -> 46056 | J25: =RIGHT(A25,4) -> 0023 | K25: =VLOOKUP(D25,客户信息表!$A$3:$H$23,5,0) -> C | L25: 李娜 | M25: 西南 | N25: =SUBSTITUTE(TRIM(M25),"区","") -> 西南 | O25: CP003 | P25: 碎纸机 SafeCut S8 | Q25: 899 | R25: 4 | S25: =IF(ISBLANK(R25),U25/Q25,VALUE(R25)) -> 4 | T25: =VLOOKUP(S25,折扣阶梯!$A$3:$C$7,2,TRUE) -> 1 | U25: 3596 | V25: =IF(Q25*S25=VALUE(SUBSTITUTE(U25,"¥","")),VALUE(SUBSTITUTE(U25,"¥","")),Q25*S25) -> 3596 | W25: 已发货 | X25: =V25*T25 -> 3596 | Y25: =_xlfn.XLOOKUP(O25,产品信息表!$A$4:$A$15,产品信息表!$E$4:$E$15) -> 620 | Z25: =(X25-Y25*S25)/X25 -> 0.31034483 | AA25: =_xlfn.RANK.EQ(V25,V25:V226,0) -> 145
A26: DD-20260206-0024 | B26: 46059 | C26: =TEXT(SUBSTITUTE(B26,".","/"),"yyyy-mm-dd") -> 2026-02-06 | D26: KH005 | E26: =VLOOKUP(D26,客户信息表!A$3:H$23,2,0) -> 杭州云图信息 | F26: 杭州云图信息 | G26: =INDEX(客户信息表!$A$4:$H$23,MATCH(F26,客户信息表!$B$4:$B$23,0),1) -> KH005 | H26: =_xlfn.XLOOKUP(O26,产品信息表!$A$4:$A$15,产品信息表!$C$4:$C$15) -> 办公耗材 | I26: =DATE(MID(A26,4,4),MID(A26,8,2),MID(A26,10,2)) -> 46059 | J26: =RIGHT(A26,4) -> 0024 | K26: =VLOOKUP(D26,客户信息表!$A$3:$H$23,5,0) -> A | L26: 刘洋 | M26: 华东 | N26: =SUBSTITUTE(TRIM(M26),"区","") -> 华东 | O26: CP010 | P26: 签字笔盒装（12支） | Q26: 45 | R26: 103 | S26: =IF(ISBLANK(R26),U26/Q26,VALUE(R26)) -> 103 | T26: =VLOOKUP(S26,折扣阶梯!$A$3:$C$7,2,TRUE) -> 0.85 | U26: 4635 | V26: =IF(Q26*S26=VALUE(SUBSTITUTE(U26,"¥","")),VALUE(SUBSTITUTE(U26,"¥","")),Q26*S26) -> 4635 | W26: 已完成 | X26: =V26*T26 -> 3939.75 | Y26: =_xlfn.XLOOKUP(O26,产品信息表!$A$4:$A$15,产品信息表!$E$4:$E$15) -> 28 | Z26: =(X26-Y26*S26)/X26 -> 0.26797386 | AA26: =_xlfn.RANK.EQ(V26,V26:V227,0) -> 134
A27: DD-20260703-0152 | B27: 46206 | C27: =TEXT(SUBSTITUTE(B27,".","/"),"yyyy-mm-dd") -> 2026-07-03 | D27: KH009 | E27: =VLOOKUP(D27,客户信息表!A$3:H$23,2,0) -> 天津海河传媒 | F27: 天津海河传媒 | G27: =INDEX(客户信息表!$A$4:$H$23,MATCH(F27,客户信息表!$B$4:$B$23,0),1) -> KH009 | H27: =_xlfn.XLOOKUP(O27,产品信息表!$A$4:$A$15,产品信息表!$C$4:$C$15) -> 办公耗材 | I27: =DATE(MID(A27,4,4),MID(A27,8,2),MID(A27,10,2)) -> 46206 | J27: =RIGHT(A27,4) -> 0152 | K27: =VLOOKUP(D27,客户信息表!$A$3:$H$23,5,0) -> C | L27: 杨帆 | M27: 华北区 | N27: =SUBSTITUTE(TRIM(M27),"区","") -> 华北 | O27: CP009 | P27: 激光硒鼓 TonerMax 12A | Q27: 385 | R27: 97 | S27: =IF(ISBLANK(R27),U27/Q27,VALUE(R27)) -> 97 | T27: =VLOOKUP(S27,折扣阶梯!$A$3:$C$7,2,TRUE) -> 0.9 | U27: 37345 | V27: =IF(Q27*S27=VALUE(SUBSTITUTE(U27,"¥","")),VALUE(SUBSTITUTE(U27,"¥","")),Q27*S27) -> 37345 | W27: 已完成 | X27: =V27*T27 -> 33610.5 | Y27: =_xlfn.XLOOKUP(O27,产品信息表!$A$4:$A$15,产品信息表!$E$4:$E$15) -> 260 | Z27: =(X27-Y27*S27)/X27 -> 0.24963925 | AA27: =_xlfn.RANK.EQ(V27,V27:V228,0) -> 17
A28: DD-20260206-0025 | B28: 46059 | C28: =TEXT(SUBSTITUTE(B28,".","/"),"yyyy-mm-dd") -> 2026-02-06 | D28: KH011 | E28: =VLOOKUP(D28,客户信息表!A$3:H$23,2,0) -> 重庆山城办公设备 | F28: 重庆山城办公设备 | G28: =INDEX(客户信息表!$A$4:$H$23,MATCH(F28,客户信息表!$B$4:$B$23,0),1) -> KH011 | H28: =_xlfn.XLOOKUP(O28,产品信息表!$A$4:$A$15,产品信息表!$C$4:$C$15) -> 办公耗材 | I28: =DATE(MID(A28,4,4),MID(A28,8,2),MID(A28,10,2)) -> 46059 | J28: =RIGHT(A28,4) -> 0025 | K28: =VLOOKUP(D28,客户信息表!$A$3:$H$23,5,0) -> B | L28: 李娜 | M28: 西南 | N28: =SUBSTITUTE(TRIM(M28),"区","") -> 西南 | O28: CP009 | P28: 激光硒鼓 TonerMax 12A | Q28: 385 | R28: 26 | S28: =IF(ISBLANK(R28),U28/Q28,VALUE(R28)) -> 26 | T28: =VLOOKUP(S28,折扣阶梯!$A$3:$C$7,2,TRUE) -> 0.95 | U28: 10010 | V28: =IF(Q28*S28=VALUE(SUBSTITUTE(U28,"¥","")),VALUE(SUBSTITUTE(U28,"¥","")),Q28*S28) -> 10010 | W28: 待付款 | X28: =V28*T28 -> 9509.5 | Y28: =_xlfn.XLOOKUP(O28,产品信息表!$A$4:$A$15,产品信息表!$E$4:$E$15) -> 260 | Z28: =(X28-Y28*S28)/X28 -> 0.28913192 | AA28: =_xlfn.RANK.EQ(V28,V28:V229,0) -> 94
A29: DD-20260208-0026 | B29: 46061 | C29: =TEXT(SUBSTITUTE(B29,".","/"),"yyyy-mm-dd") -> 2026-02-08 | D29: KH002 | E29: =VLOOKUP(D29,客户信息表!A$3:H$23,2,0) -> 上海锦程贸易 | F29: 上海锦程贸易 | G29: =INDEX(客户信息表!$A$4:$H$23,MATCH(F29,客户信息表!$B$4:$B$23,0),1) -> KH002 | H29: =_xlfn.XLOOKUP(O29,产品信息表!$A$4:$A$15,产品信息表!$C$4:$C$15) -> 电子数码 | I29: =DATE(MID(A29,4,4),MID(A29,8,2),MID(A29,10,2)) -> 46061 | J29: =RIGHT(A29,4) -> 0026 | K29: =VLOOKUP(D29,客户信息表!$A$3:$H$23,5,0) -> B | L29: 张伟 | M29: 华东 | N29: =SUBSTITUTE(TRIM(M29),"区","") -> 华东 | O29: CP007 | P29: 无线键鼠套装 KeyFree 2.0 | Q29: 299 | R29: 2 | S29: =IF(ISBLANK(R29),U29/Q29,VALUE(R29)) -> 2 | T29: =VLOOKUP(S29,折扣阶梯!$A$3:$C$7,2,TRUE) -> 1 | U29: 598 | V29: =IF(Q29*S29=VALUE(SUBSTITUTE(U29,"¥","")),VALUE(SUBSTITUTE(U29,"¥","")),Q29*S29) -> 598 | W29: 已发货 | X29: =V29*T29 -> 598 | Y29: =_xlfn.XLOOKUP(O29,产品信息表!$A$4:$A$15,产品信息表!$E$4:$E$15) -> 190 | Z29: =(X29-Y29*S29)/X29 -> 0.36454849 | AA29: =_xlfn.RANK.EQ(V29,V29:V230,0) -> 173
A30: DD-20260216-0027 | B30: 46069 | C30: =TEXT(SUBSTITUTE(B30,".","/"),"yyyy-mm-dd") -> 2026-02-16 | D30: KH014 | E30: =VLOOKUP(D30,客户信息表!A$3:H$23,2,0) -> 宁波海港实业 | F30: 宁波海港实业 | G30: =INDEX(客户信息表!$A$4:$H$23,MATCH(F30,客户信息表!$B$4:$B$23,0),1) -> KH014 | H30: =_xlfn.XLOOKUP(O30,产品信息表!$A$4:$A$15,产品信息表!$C$4:$C$15) -> 电子数码 | I30: =DATE(MID(A30,4,4),MID(A30,8,2),MID(A30,10,2)) -> 46069 | J30: =RIGHT(A30,4) -> 0027 | K30: =VLOOKUP(D30,客户信息表!$A$3:$H$23,5,0) -> B | L30: 李娜 | M30: 华东区 | N30: =SUBSTITUTE(TRIM(M30),"区","") -> 华东 | O30: CP004 | P30: 笔记本电脑 TechBook 14 | Q30: 5699 | R30: 11 | S30: =IF(ISBLANK(R30),U30/Q30,VALUE(R30)) -> 11 | T30: =VLOOKUP(S30,折扣阶梯!$A$3:$C$7,2,TRUE) -> 0.95 | U30: ¥62,689.00 | V30: =IF(Q30*S30=VALUE(SUBSTITUTE(U30,"¥","")),VALUE(SUBSTITUTE(U30,"¥","")),Q30*S30) -> 62689 | W30: 已完成 | X30: =V30*T30 -> 59554.55 | Y30: =_xlfn.XLOOKUP(O30,产品信息表!$A$4:$A$15,产品信息表!$E$4:$E$15) -> 4800 | Z30: =(X30-Y30*S30)/X30 -> 0.11341787 | AA30: =_xlfn.RANK.EQ(V30,V30:V231,0) -> 4
A31: DD-20260221-0028 | B31: 2026.2.21 | C31: =TEXT(SUBSTITUTE(B31,".","/"),"yyyy-mm-dd") -> 2026-02-21 | D31: KH005 | E31: =VLOOKUP(D31,客户信息表!A$3:H$23,2,0) -> 杭州云图信息 | F31: 杭州云图信息 | G31: =INDEX(客户信息表!$A$4:$H$23,MATCH(F31,客户信息表!$B$4:$B$23,0),1) -> KH005 | H31: =_xlfn.XLOOKUP(O31,产品信息表!$A$4:$A$15,产品信息表!$C$4:$C$15) -> 软件服务 | I31: =DATE(MID(A31,4,4),MID(A31,8,2),MID(A31,10,2)) -> 46074 | J31: =RIGHT(A31,4) -> 0028 | K31: =VLOOKUP(D31,客户信息表!$A$3:$H$23,5,0) -> A | L31: 杨帆 | M31: 华东 | N31: =SUBSTITUTE(TRIM(M31),"区","") -> 华东 | O31: CP011 | P31: 办公软件年费授权 | Q31: 699 | R31: 20 | S31: =IF(ISBLANK(R31),U31/Q31,VALUE(R31)) -> 20 | T31: =VLOOKUP(S31,折扣阶梯!$A$3:$C$7,2,TRUE) -> 0.95 | U31: 13980 | V31: =IF(Q31*S31=VALUE(SUBSTITUTE(U31,"¥","")),VALUE(SUBSTITUTE(U31,"¥","")),Q31*S31) -> 13980 | W31: 已完成 | X31: =V31*T31 -> 13281 | Y31: =_xlfn.XLOOKUP(O31,产品信息表!$A$4:$A$15,产品信息表!$E$4:$E$15) -> 300 | Z31: =(X31-Y31*S31)/X31 -> 0.54822679 | AA31: =_xlfn.RANK.EQ(V31,V31:V232,0) -> 76
A32: DD-20260221-0029 | B32: 46074 | C32: =TEXT(SUBSTITUTE(B32,".","/"),"yyyy-mm-dd") -> 2026-02-21 | D32: KH005 | E32: =VLOOKUP(D32,客户信息表!A$3:H$23,2,0) -> 杭州云图信息 | F32: 杭州云图信息 | G32: =INDEX(客户信息表!$A$4:$H$23,MATCH(F32,客户信息表!$B$4:$B$23,0),1) -> KH005 | H32: =_xlfn.XLOOKUP(O32,产品信息表!$A$4:$A$15,产品信息表!$C$4:$C$15) -> 办公设备 | I32: =DATE(MID(A32,4,4),MID(A32,8,2),MID(A32,10,2)) -> 46074 | J32: =RIGHT(A32,4) -> 0029 | K32: =VLOOKUP(D32,客户信息表!$A$3:$H$23,5,0) -> A | L32: 赵磊 | M32: 华东 | N32: =SUBSTITUTE(TRIM(M32),"区","") -> 华东 | O32: CP001 | P32: 激光打印机 ProLaser 200 | Q32: 2499 | R32: 5 | S32: =IF(ISBLANK(R32),U32/Q32,VALUE(R32)) -> 5 | T32: =VLOOKUP(S32,折扣阶梯!$A$3:$C$7,2,TRUE) -> 1 | U32: 12495 | V32: =IF(Q32*S32=VALUE(SUBSTITUTE(U32,"¥","")),VALUE(SUBSTITUTE(U32,"¥","")),Q32*S32) -> 12495 | W32: 已取消 | X32: =V32*T32 -> 12495 | Y32: =_xlfn.XLOOKUP(O32,产品信息表!$A$4:$A$15,产品信息表!$E$4:$E$15) -> 1850 | Z32: =(X32-Y32*S32)/X32 -> 0.25970388 | AA32: =_xlfn.RANK.EQ(V32,V32:V233,0) -> 83
A33: DD-20260512-0102 | B33: 46154 | C33: =TEXT(SUBSTITUTE(B33,".","/"),"yyyy-mm-dd") -> 2026-05-12 | D33: KH014 | E33: =VLOOKUP(D33,客户信息表!A$3:H$23,2,0) -> 宁波海港实业 | F33: 宁波海港实业 | G33: =INDEX(客户信息表!$A$4:$H$23,MATCH(F33,客户信息表!$B$4:$B$23,0),1) -> KH014 | H33: =_xlfn.XLOOKUP(O33,产品信息表!$A$4:$A$15,产品信息表!$C$4:$C$15) -> 电子数码 | I33: =DATE(MID(A33,4,4),MID(A33,8,2),MID(A33,10,2)) -> 46154 | J33: =RIGHT(A33,4) -> 0102 | K33: =VLOOKUP(D33,客户信息表!$A$3:$H$23,5,0) -> B | L33: 王强 | M33: 华东 | N33: =SUBSTITUTE(TRIM(M33),"区","") -> 华东 | O33: CP004 | P33: 笔记本电脑 TechBook 14 | Q33: 5699 | R33: 13 | S33: =IF(ISBLANK(R33),U33/Q33,VALUE(R33)) -> 13 | T33: =VLOOKUP(S33,折扣阶梯!$A$3:$C$7,2,TRUE) -> 0.95 | U33: 74087 | V33: =IF(Q33*S33=VALUE(SUBSTITUTE(U33,"¥","")),VALUE(SUBSTITUTE(U33,"¥","")),Q33*S33) -> 74087 | W33: 已发货 | X33: =V33*T33 -> 70382.65 | Y33: =_xlfn.XLOOKUP(O33,产品信息表!$A$4:$A$15,产品信息表!$E$4:$E$15) -> 4800 | Z33: =(X33-Y33*S33)/X33 -> 0.11341787 | AA33: =_xlfn.RANK.EQ(V33,V33:V234,0) -> 1
A34: DD-20260223-0030 | B34: 46076 | C34: =TEXT(SUBSTITUTE(B34,".","/"),"yyyy-mm-dd") -> 2026-02-23 | D34: KH001 | E34: =VLOOKUP(D34,客户信息表!A$3:H$23,2,0) -> 北京华信科技 | F34: 北京华信科技 | G34: =INDEX(客户信息表!$A$4:$H$23,MATCH(F34,客户信息表!$B$4:$B$23,0),1) -> KH001 | H34: =_xlfn.XLOOKUP(O34,产品信息表!$A$4:$A$15,产品信息表!$C$4:$C$15) -> 电子数码 | I34: =DATE(MID(A34,4,4),MID(A34,8,2),MID(A34,10,2)) -> 46076 | J34: =RIGHT(A34,4) -> 0030 | K34: =VLOOKUP(D34,客户信息表!$A$3:$H$23,5,0) -> A | L34: 李娜 | M34: 华北 | N34: =SUBSTITUTE(TRIM(M34),"区","") -> 华北 | O34: CP004 | P34: 笔记本电脑 TechBook 14 | Q34: 5699 | R34: 5 | S34: =IF(ISBLANK(R34),U34/Q34,VALUE(R34)) -> 5 | T34: =VLOOKUP(S34,折扣阶梯!$A$3:$C$7,2,TRUE) -> 1 | U34: 28495 | V34: =IF(Q34*S34=VALUE(SUBSTITUTE(U34,"¥","")),VALUE(SUBSTITUTE(U34,"¥","")),Q34*S34) -> 28495 | W34: 已完成 | X34: =V34*T34 -> 28495 | Y34: =_xlfn.XLOOKUP(O34,产品信息表!$A$4:$A$15,产品信息表!$E$4:$E$15) -> 4800 | Z34: =(X34-Y34*S34)/X34 -> 0.15774697 | AA34: =_xlfn.RANK.EQ(V34,V34:V235,0) -> 23
A35: DD-20260227-0031 | B35: 46080 | C35: =TEXT(SUBSTITUTE(B35,".","/"),"yyyy-mm-dd") -> 2026-02-27 | D35: KH011 | E35: =VLOOKUP(D35,客户信息表!A$3:H$23,2,0) -> 重庆山城办公设备 | F35: 重庆山城办公设备 | G35: =INDEX(客户信息表!$A$4:$H$23,MATCH(F35,客户信息表!$B$4:$B$23,0),1) -> KH011 | H35: =_xlfn.XLOOKUP(O35,产品信息表!$A$4:$A$15,产品信息表!$C$4:$C$15) -> 软件服务 | I35: =DATE(MID(A35,4,4),MID(A35,8,2),MID(A35,10,2)) -> 46080 | J35: =RIGHT(A35,4) -> 0031 | K35: =VLOOKUP(D35,客户信息表!$A$3:$H$23,5,0) -> B | L35: 杨帆 | M35: 西南 | N35: =SUBSTITUTE(TRIM(M35),"区","") -> 西南 | O35: CP012 | P35: 云存储服务（1TB/年） | Q35: 599 | R35: 24 | S35: =IF(ISBLANK(R35),U35/Q35,VALUE(R35)) -> 24 | T35: =VLOOKUP(S35,折扣阶梯!$A$3:$C$7,2,TRUE) -> 0.95 | U35: 14376 | V35: =IF(Q35*S35=VALUE(SUBSTITUTE(U35,"¥","")),VALUE(SUBSTITUTE(U35,"¥","")),Q35*S35) -> 14376 | W35: 已发货 | X35: =V35*T35 -> 13657.2 | Y35: =_xlfn.XLOOKUP(O35,产品信息表!$A$4:$A$15,产品信息表!$E$4:$E$15) -> 250 | Z35: =(X35-Y35*S35)/X35 -> 0.56067129 | AA35: =_xlfn.RANK.EQ(V35,V35:V236,0) -> 71
A36: DD-20260308-0037 | B36: 46089 | C36: =TEXT(SUBSTITUTE(B36,".","/"),"yyyy-mm-dd") -> 2026-03-08 | D36: KH008 | E36: =VLOOKUP(D36,客户信息表!A$3:H$23,2,0) -> 南京紫金山软件园运营 | F36: 南京紫金山软件园运营 | G36: =INDEX(客户信息表!$A$4:$H$23,MATCH(F36,客户信息表!$B$4:$B$23,0),1) -> KH008 | H36: =_xlfn.XLOOKUP(O36,产品信息表!$A$4:$A$15,产品信息表!$C$4:$C$15) -> 办公耗材 | I36: =DATE(MID(A36,4,4),MID(A36,8,2),MID(A36,10,2)) -> 46089 | J36: =RIGHT(A36,4) -> 0037 | K36: =VLOOKUP(D36,客户信息表!$A$3:$H$23,5,0) -> C | L36: 杨帆 | M36: 华东 | N36: =SUBSTITUTE(TRIM(M36),"区","") -> 华东 | O36: CP008 | P36: A4复印纸（5包/箱） | Q36: 128 | R36: 12 | S36: =IF(ISBLANK(R36),U36/Q36,VALUE(R36)) -> 12 | T36: =VLOOKUP(S36,折扣阶梯!$A$3:$C$7,2,TRUE) -> 0.95 | U36: 1536 | V36: =IF(Q36*S36=VALUE(SUBSTITUTE(U36,"¥","")),VALUE(SUBSTITUTE(U36,"¥","")),Q36*S36) -> 1536 | W36: 已完成 | X36: =V36*T36 -> 1459.2 | Y36: =_xlfn.XLOOKUP(O36,产品信息表!$A$4:$A$15,产品信息表!$E$4:$E$15) -> 95 | Z36: =(X36-Y36*S36)/X36 -> 0.21875 | AA36: =_xlfn.RANK.EQ(V36,V36:V237,0) -> 158
A37: DD-20260227-0032 | B37: 2026/2/27 | C37: =TEXT(SUBSTITUTE(B37,".","/"),"yyyy-mm-dd") -> 2026-02-27 | D37: KH012 | E37: =VLOOKUP(D37,客户信息表!A$3:H$23,2,0) -> 长沙麓山科技 | F37: 长沙麓山科技 | G37: =INDEX(客户信息表!$A$4:$H$23,MATCH(F37,客户信息表!$B$4:$B$23,0),1) -> KH012 | H37: =_xlfn.XLOOKUP(O37,产品信息表!$A$4:$A$15,产品信息表!$C$4:$C$15) -> 办公耗材 | I37: =DATE(MID(A37,4,4),MID(A37,8,2),MID(A37,10,2)) -> 46080 | J37: =RIGHT(A37,4) -> 0032 | K37: =VLOOKUP(D37,客户信息表!$A$3:$H$23,5,0) -> B | L37: 张伟 | M37: 华中 | N37: =SUBSTITUTE(TRIM(M37),"区","") -> 华中 | O37: CP009 | P37: 激光硒鼓 TonerMax 12A | Q37: 385 | R37: 88 | S37: =IF(ISBLANK(R37),U37/Q37,VALUE(R37)) -> 88 | T37: =VLOOKUP(S37,折扣阶梯!$A$3:$C$7,2,TRUE) -> 0.9 | U37: 33880 | V37: =IF(Q37*S37=VALUE(SUBSTITUTE(U37,"¥","")),VALUE(SUBSTITUTE(U37,"¥","")),Q37*S37) -> 33880 | W37: 已取消 | X37: =V37*T37 -> 30492 | Y37: =_xlfn.XLOOKUP(O37,产品信息表!$A$4:$A$15,产品信息表!$E$4:$E$15) -> 260 | Z37: =(X37-Y37*S37)/X37 -> 0.24963925 | AA37: =_xlfn.RANK.EQ(V37,V37:V238,0) -> 19
A38: DD-20260228-0033 | B38: 46081 | C38: =TEXT(SUBSTITUTE(B38,".","/"),"yyyy-mm-dd") -> 2026-02-28 | D38: KH005 | E38: =VLOOKUP(D38,客户信息表!A$3:H$23,2,0) -> 杭州云图信息 | F38: 杭州云图信息 | G38: =INDEX(客户信息表!$A$4:$H$23,MATCH(F38,客户信息表!$B$4:$B$23,0),1) -> KH005 | H38: =_xlfn.XLOOKUP(O38,产品信息表!$A$4:$A$15,产品信息表!$C$4:$C$15) -> 电子数码 | I38: =DATE(MID(A38,4,4),MID(A38,8,2),MID(A38,10,2)) -> 46081 | J38: =RIGHT(A38,4) -> 0033 | K38: =VLOOKUP(D38,客户信息表!$A$3:$H$23,5,0) -> A | L38: 赵磊 | M38: 华东区 | N38: =SUBSTITUTE(TRIM(M38),"区","") -> 华东 | O38: CP004 | P38: 笔记本电脑 TechBook 14 | Q38: 5699 | R38: 8 | S38: =IF(ISBLANK(R38),U38/Q38,VALUE(R38)) -> 8 | T38: =VLOOKUP(S38,折扣阶梯!$A$3:$C$7,2,TRUE) -> 1 | U38: ¥45,592.00 | V38: =IF(Q38*S38=VALUE(SUBSTITUTE(U38,"¥","")),VALUE(SUBSTITUTE(U38,"¥","")),Q38*S38) -> 45592 | W38: 已取消 | X38: =V38*T38 -> 45592 | Y38: =_xlfn.XLOOKUP(O38,产品信息表!$A$4:$A$15,产品信息表!$E$4:$E$15) -> 4800 | Z38: =(X38-Y38*S38)/X38 -> 0.15774697 | AA38: =_xlfn.RANK.EQ(V38,V38:V239,0) -> 8
A39: DD-20260303-0034 | B39: 46084 | C39: =TEXT(SUBSTITUTE(B39,".","/"),"yyyy-mm-dd") -> 2026-03-03 | D39: KH017 | E39: =VLOOKUP(D39,客户信息表!A$3:H$23,2,0) -> 郑州中原物流 | F39: 郑州中原物流 | G39: =INDEX(客户信息表!$A$4:$H$23,MATCH(F39,客户信息表!$B$4:$B$23,0),1) -> KH017 | H39: =_xlfn.XLOOKUP(O39,产品信息表!$A$4:$A$15,产品信息表!$C$4:$C$15) -> 办公耗材 | I39: =DATE(MID(A39,4,4),MID(A39,8,2),MID(A39,10,2)) -> 46084 | J39: =RIGHT(A39,4) -> 0034 | K39: =VLOOKUP(D39,客户信息表!$A$3:$H$23,5,0) -> B | L39: 陈静 | M39: 华中 | N39: =SUBSTITUTE(TRIM(M39),"区","") -> 华中 | O39: CP009 | P39: 激光硒鼓 TonerMax 12A | Q39: 385 | R39: 120 | S39: =IF(ISBLANK(R39),U39/Q39,VALUE(R39)) -> 120 | T39: =VLOOKUP(S39,折扣阶梯!$A$3:$C$7,2,TRUE) -> 0.85 | U39: 46200 | V39: =IF(Q39*S39=VALUE(SUBSTITUTE(U39,"¥","")),VALUE(SUBSTITUTE(U39,"¥","")),Q39*S39) -> 46200 | W39: 已完成 | X39: =V39*T39 -> 39270 | Y39: =_xlfn.XLOOKUP(O39,产品信息表!$A$4:$A$15,产品信息表!$E$4:$E$15) -> 260 | Z39: =(X39-Y39*S39)/X39 -> 0.20550038 | AA39: =_xlfn.RANK.EQ(V39,V39:V240,0) -> 7
A40: DD-20260306-0035 | B40: 46087 | C40: =TEXT(SUBSTITUTE(B40,".","/"),"yyyy-mm-dd") -> 2026-03-06 | D40: KH019 | E40: =VLOOKUP(D40,客户信息表!A$3:H$23,2,0) -> 北京中关新材 | F40: 北京中关新材 | G40: =INDEX(客户信息表!$A$4:$H$23,MATCH(F40,客户信息表!$B$4:$B$23,0),1) -> KH019 | H40: =_xlfn.XLOOKUP(O40,产品信息表!$A$4:$A$15,产品信息表!$C$4:$C$15) -> 电子数码 | I40: =DATE(MID(A40,4,4),MID(A40,8,2),MID(A40,10,2)) -> 46087 | J40: =RIGHT(A40,4) -> 0035 | K40: =VLOOKUP(D40,客户信息表!$A$3:$H$23,5,0) -> B | L40: 赵磊 | M40: 华北 | N40: =SUBSTITUTE(TRIM(M40),"区","") -> 华北 | O40: CP006 | P40: 显示器 ViewMax 27 | Q40: 1299 | R40: 12 | S40: =IF(ISBLANK(R40),U40/Q40,VALUE(R40)) -> 12 | T40: =VLOOKUP(S40,折扣阶梯!$A$3:$C$7,2,TRUE) -> 0.95 | U40: 15588 | V40: =IF(Q40*S40=VALUE(SUBSTITUTE(U40,"¥","")),VALUE(SUBSTITUTE(U40,"¥","")),Q40*S40) -> 15588 | W40: 待付款 | X40: =V40*T40 -> 14808.6 | Y40: =_xlfn.XLOOKUP(O40,产品信息表!$A$4:$A$15,产品信息表!$E$4:$E$15) -> 950 | Z40: =(X40-Y40*S40)/X40 -> 0.23017706 | AA40: =_xlfn.RANK.EQ(V40,V40:V241,0) -> 58
...

Sheet 客户信息表
A1: 客户主数据（20家）
A2: 客户等级：A=重点客户 B=普通客户 C=小额客户。查找练习的标准数据源。
A3: 客户ID | B3: 客户名称 | C3: 所属区域 | D3: 所属行业 | E3: 客户等级 | F3: 信用额度(万元) | G3: 账期(天) | H3: 合作起始日期
A4: KH001 | B4: 北京华信科技 | C4: 华北 | D4: 互联网 | E4: A | F4: 55 | G4: 30 | H4: 43536
A5: KH002 | B5: 上海锦程贸易 | C5: 华东 | D5: 零售 | E5: B | F5: 32 | G5: 45 | H5: 43983
A6: KH003 | B6: 广州启航教育 | C6: 华南 | D6: 教育 | E6: A | F6: 60 | G6: 30 | H6: 43363
A7: KH004 | B7: 深圳蓝鲸网络 | C7: 华南 | D7: 互联网 | E7: B | F7: 40 | G7: 30 | H7: 44211
A8: KH005 | B8: 杭州云图信息 | C8: 华东 | D8: 互联网 | E8: A | F8: 50 | G8: 60 | H8: 44143
A9: KH006 | B9: 成都天府商贸 | C9: 西南 | D9: 零售 | E9: C | F9: 20 | G9: 45 | H9: 44625
A10: KH007 | B10: 武汉长江实业 | C10: 华中 | D10: 制造业 | E10: B | F10: 35 | G10: 60 | H10: 43668
A11: KH008 | B11: 南京紫金山软件园运营 | C11: 华东 | D11: 互联网 | E11: C | F11: 25 | G11: 30 | H11: 44438
A12: KH009 | B12: 天津海河传媒 | C12: 华北 | D12: 文化传媒 | E12: C | F12: 15 | G12: 45 | H12: 44698
A13: KH010 | B13: 苏州创智科技 | C13: 华东 | D13: 制造业 | E13: A | F13: 55 | G13: 30 | H13: 43887
A14: KH011 | B14: 重庆山城办公设备 | C14: 西南 | D14: 零售 | E14: B | F14: 28 | G14: 45 | H14: 44480
A15: KH012 | B15: 长沙麓山科技 | C15: 华中 | D15: 互联网 | E15: B | F15: 32 | G15: 30 | H15: 44168
... A23: KH020 | B23: 合肥科大国创 | C23: 华东 | D23: 教育 | E23: C | F23: 22 | G23: 45 | H23: 44571

Sheet 产品信息表
A1: 产品主数据（12个）
A2: 毛利计算数据源：毛利 = 标准单价 × 数量 − 单位成本 × 数量（结合折扣另算，见题目）。
A3: 产品编码 | B3: 产品名称 | C3: 类别 | D3: 标准单价(元) | E3: 单位成本(元) | F3: 供应商
A4: CP001 | B4: 激光打印机 ProLaser 200 | C4: 办公设备 | D4: 2499 | E4: 1850 | F4: 惠普商用分销
A5: CP002 | B5: 多功能一体机 PrintMaster 300 | C5: 办公设备 | D5: 3599 | E5: 2700 | F5: 佳能(中国)
A6: CP003 | B6: 碎纸机 SafeCut S8 | C6: 办公设备 | D6: 899 | E6: 620 | F6: 得力集团
A7: CP004 | B7: 笔记本电脑 TechBook 14 | C7: 电子数码 | D7: 5699 | E7: 4800 | F7: 联想授权经销商
A8: CP005 | B8: 台式电脑 PowerDesk 500 | C8: 电子数码 | D8: 4299 | E8: 3500 | F8: 联想授权经销商
A9: CP006 | B9: 显示器 ViewMax 27 | C9: 电子数码 | D9: 1299 | E9: 950 | F9: 戴尔金牌店
A10: CP007 | B10: 无线键鼠套装 KeyFree 2.0 | C10: 电子数码 | D10: 299 | E10: 190 | F10: 罗技分销
A11: CP008 | B11: A4复印纸（5包/箱） | C11: 办公耗材 | D11: 128 | E11: 95 | F11: 得力集团
A12: CP009 | B12: 激光硒鼓 TonerMax 12A | C12: 办公耗材 | D12: 385 | E12: 260 | F12: 格之格
A13: CP010 | B13: 签字笔盒装（12支） | C13: 办公耗材 | D13: 45 | E13: 28 | F13: 晨光文具
A14: CP011 | B14: 办公软件年费授权 | C14: 软件服务 | D14: 699 | E14: 300 | F14: 金山软件
A15: CP012 | B15: 云存储服务（1TB/年） | C15: 软件服务 | D15: 599 | E15: 250 | F15: 阿里云渠道

Sheet 折扣阶梯
A1: 数量折扣阶梯表
A2: VLOOKUP 近似匹配（第4参数TRUE）练习用。注意：首列必须升序排列才能正确匹配。
A3: 数量下限(件) | B3: 折扣率 | C3: 说明
A4: 1 | B4: 1 | C4: 1~9件 按原价
A5: 10 | B5: 0.95 | C5: 10~49件 95折
A6: 50 | B6: 0.9 | C6: 50~99件 9折
A7: 100 | B7: 0.85 | C7: 100件及以上 85折

Sheet 详细信息1
A1: 求和项:金额(修正后) - 区域(修正后): 华北, 月(日期): Jan 的详细信息
A3: 订单编号 | B3: 下单日期 | C3: 下单日期(修正后) | D3: 客户ID | E3: 客户名称(修正后) | F3: 客户名称 | G3: 客户ID(修正后) | H3: 字段8 | I3: 日期 | J3: 流水号 | K3: 用户登记（修正后） | L3: 销售员 | M3: 区域 | N3: 区域(修正后) | O3: 产品编码 | P3: 产品名称 | Q3: 单价(元) | R3: 数量 | S3: 修正后 | T3: 折扣(修正后) | U3: 金额(元) | V3: 金额(修正后) | W3: 订单状态 | X3: 应收金额
A4: DD-20260126-0015 | B4: 46048 | C4: 2026-01-26 | D4: KH019 | E4: 北京中关新材 | F4: 北京中关新材 | G4: KH019 | H4: KH019 | I4: 46048 | J4: 0015 | K4: B | L4: 孙悦 | M4: 华北 | N4: 华北 | O4: CP001 | P4: 激光打印机 ProLaser 200 | Q4: 2499 | S4: 4 | T4: 1 | U4: 9996 | V4: 9996 | W4: 已发货 | X4: 9996
A5: DD-20260125-0014 | B5: 46047 | C5: 2026-01-25 | D5: KH001 | E5: 北京华信科技 | F5: 北京华信科技 | G5: KH001 | H5: KH001 | I5: 46047 | J5: 0014 | K5: A | L5: 张伟 | M5: 华北 | N5: 华北 | O5: CP009 | P5: 激光硒鼓 TonerMax 12A | Q5: 385 | R5: 32 | S5: 32 | T5: 0.95 | U5: 12320 | V5: 12320 | W5: 已发货 | X5: 11704
A6: DD-20260120-0010 | B6: 46042 | C6: 2026-01-20 | D6: KH019 | E6: 北京中关新材 | F6: 北京中关新材 | G6: KH019 | H6: KH019 | I6: 46042 | J6: 0010 | K6: B | L6: 孙悦 | M6: 华北 | N6: 华北 | O6: CP012 | P6: 云存储服务（1TB/年） | Q6: 599 | R6: 3 | S6: 3 | T6: 1 | U6: 1797 | V6: 1797 | W6: 已完成 | X6: 1797
A7: DD-20260109-0007 | B7: 46031 | C7: 2026-01-09 | D7: KH019 | E7: 北京中关新材 | F7: 北京中关新材 | G7: KH019 | H7: KH019 | I7: 46031 | J7: 0007 | K7: B | L7: 陈静 | M7: 华北 | N7: 华北 | O7: CP010 | P7: 签字笔盒装（12支） | Q7: 45 | R7: 85 | S7: 85 | T7: 0.9 | U7: 3825 | V7: 3825 | W7: 已完成 | X7: 3442.5

Sheet 销售目标
A1: 2026年1-8月 各区域销售目标（元）
A2: 完成率练习：实际 = 清洗后订单表按区域汇总金额；是否剔除「已取消」订单由自己定口径并说明。
A3: 区域 | B3: 2026-01 | C3: 2026-02 | D3: 2026-03 | E3: 2026-04 | F3: 2026-05 | G3: 2026-06 | H3: 2026-07 | I3: 2026-08 | J3: 合计
A4: 华东 | B4: 23000 | C4: 129000 | D4: 108000 | E4: 104000 | F4: 292000 | G4: 110000 | H4: 162000 | I4: 82000 | J4: =SUM(B4:I4) -> 1010000
A5: 华北 | B5: 29000 | C5: 30000 | D5: 77000 | E5: 23000 | F5: 143000 | G5: 122000 | H5: 116000 | I5: 43000 | J5: =SUM(B5:I5) -> 583000
A6: 华南 | B6: 8000 | C6: 8000 | D6: 17000 | E6: 114000 | F6: 127000 | G6: 49000 | H6: 43000 | I6: 46000 | J6: =SUM(B6:I6) -> 412000
A7: 西南 | B7: 39000 | C7: 25000 | D7: 46000 | E7: 57000 | F7: 24000 | G7: 46000 | H7: 79000 | I7: 60000 | J7: =SUM(B7:I7) -> 376000
A8: 华中 | B8: 50000 | C8: 43000 | D8: 51000 | E8: 27000 | F8: 94000 | G8: 58000 | H8: 26000 | I8: 84000 | J8: =SUM(B8:I8) -> 433000
A9: 总计 | B9: =SUM(B4:B8) -> 149000 | C9: =SUM(C4:C8) -> 235000 | D9: =SUM(D4:D8) -> 299000 | E9: =SUM(E4:E8) -> 325000 | F9: =SUM(F4:F8) -> 680000 | G9: =SUM(G4:G8) -> 385000 | H9: =SUM(H4:H8) -> 426000 | I9: =SUM(I4:I8) -> 315000 | J9: =SUM(J4:J8) -> 2814000
A16: 求和项:金额(修正后) | B16: 列标签
A17: 行标签 | B17: 1月 | C17: 2月 | D17: 3月 | E17: 4月 | F17: 5月 | G17: 6月 | H17: 7月 | I17: 8月 | J17: 总计
A18: 华北 | B18: 27938 | C18: 28495 | D18: 72200 | E18: 21881 | F18: 102625 | G18: 114784 | H18: 109154 | I18: 40329 | J18: 517406
A19: 华东 | B19: 22857 | C19: 81902 | D19: 132603 | E19: 140398 | F19: 246587 | G19: 99600 | H19: 169804 | I19: 88661 | J19: 982412
A20: 华南 | B20: 899 | D20: 7493 | E20: 118532 | F20: 132452 | G20: 51222 | H20: 44867 | I20: 47679 | J20: 403144
A21: 华中 | B21: 45734 | D21: 47099 | E21: 25193 | F21: 82255 | G21: 46471 | H21: 23569 | I21: 77390 | J21: 347711
A22: 西南 | B22: 44649 | C22: 27982 | D22: 51828 | E22: 82246 | F22: 23121 | G22: 51800 | H22: 89874 | I22: 67642 | J22: 439142
A23: 总计 | B23: 142077 | C23: 138379 | D23: 311223 | E23: 388250 | F23: 587040 | G23: 363877 | H23: 437268 | I23: 321701 | J23: 2689815
A26: 华北 | B26: =VLOOKUP($A26,$A$17:$J$23,COLUMN(B3),0)/VLOOKUP($A26,$A$3:$J$9,COLUMN(B3),0) -> 0.96337931 | C26: =VLOOKUP($A26,$A$17:$J$23,COLUMN(C3),0)/VLOOKUP($A26,$A$3:$J$9,COLUMN(C3),0) -> 0.94983333 | D26: =VLOOKUP($A26,$A$17:$J$23,COLUMN(D3),0)/VLOOKUP($A26,$A$3:$J$9,COLUMN(D3),0) -> 0.93766234 | E26: =VLOOKUP($A26,$A$17:$J$23,COLUMN(E3),0)/VLOOKUP($A26,$A$3:$J$9,COLUMN(E3),0) -> 0.95134783 | F26: =VLOOKUP($A26,$A$17:$J$23,COLUMN(F3),0)/VLOOKUP($A26,$A$3:$J$9,COLUMN(F3),0) -> 0.71765734 | G26: =VLOOKUP($A26,$A$17:$J$23,COLUMN(G3),0)/VLOOKUP($A26,$A$3:$J$9,COLUMN(G3),0) -> 0.94085246 | H26: =VLOOKUP($A26,$A$17:$J$23,COLUMN(H3),0)/VLOOKUP($A26,$A$3:$J$9,COLUMN(H3),0) -> 0.94098276 | I26: =VLOOKUP($A26,$A$17:$J$23,COLUMN(I3),0)/VLOOKUP($A26,$A$3:$J$9,COLUMN(I3),0) -> 0.93788372 | J26: =VLOOKUP($A26,$A$17:$J$23,COLUMN(J3),0)/VLOOKUP($A26,$A$3:$J$9,COLUMN(J3),0) -> 0.88748885
A27: 华东 | B27: =VLOOKUP($A27,$A$17:$J$23,COLUMN(B4),0)/VLOOKUP($A27,$A$3:$J$9,COLUMN(B4),0) -> 0.99378261 | C27: =VLOOKUP($A27,$A$17:$J$23,COLUMN(C4),0)/VLOOKUP($A27,$A$3:$J$9,COLUMN(C4),0) -> 0.63489922 | D27: =VLOOKUP($A27,$A$17:$J$23,COLUMN(D4),0)/VLOOKUP($A27,$A$3:$J$9,COLUMN(D4),0) -> 1.2278056 | E27: =VLOOKUP($A27,$A$17:$J$23,COLUMN(E4),0)/VLOOKUP($A27,$A$3:$J$9,COLUMN(E4),0) -> 1.3499808 | F27: =VLOOKUP($A27,$A$17:$J$23,COLUMN(F4),0)/VLOOKUP($A27,$A$3:$J$9,COLUMN(F4),0) -> 0.84447603 | G27: =VLOOKUP($A27,$A$17:$J$23,COLUMN(G4),0)/VLOOKUP($A27,$A$3:$J$9,COLUMN(G4),0) -> 0.90545455 | H27: =VLOOKUP($A27,$A$17:$J$23,COLUMN(H4),0)/VLOOKUP($A27,$A$3:$J$9,COLUMN(H4),0) -> 1.0481728 | I27: =VLOOKUP($A27,$A$17:$J$23,COLUMN(I4),0)/VLOOKUP($A27,$A$3:$J$9,COLUMN(I4),0) -> 1.0812317 | J27: =VLOOKUP($A27,$A$17:$J$23,COLUMN(J4),0)/VLOOKUP($A27,$A$3:$J$9,COLUMN(J4),0) -> 0.97268515
A28: 华南 | B28: =VLOOKUP($A28,$A$17:$J$23,COLUMN(B5),0)/VLOOKUP($A28,$A$3:$J$9,COLUMN(B5),0) -> 0.112375 | C28: =VLOOKUP($A28,$A$17:$J$23,COLUMN(C5),0)/VLOOKUP($A28,$A$3:$J$9,COLUMN(C5),0) -> 0 | D28: =VLOOKUP($A28,$A$17:$J$23,COLUMN(D5),0)/VLOOKUP($A28,$A$3:$J$9,COLUMN(D5),0) -> 0.44076471 | E28: =VLOOKUP($A28,$A$17:$J$23,COLUMN(E5),0)/VLOOKUP($A28,$A$3:$J$9,COLUMN(E5),0) -> 1.0397544 | F28: =VLOOKUP($A28,$A$17:$J$23,COLUMN(F5),0)/VLOOKUP($A28,$A$3:$J$9,COLUMN(F5),0) -> 1.0429291 | G28: =VLOOKUP($A28,$A$17:$J$23,COLUMN(G5),0)/VLOOKUP($A28,$A$3:$J$9,COLUMN(G5),0) -> 1.0453469 | H28: =VLOOKUP($A28,$A$17:$J$23,COLUMN(H5),0)/VLOOKUP($A28,$A$3:$J$9,COLUMN(H5),0) -> 1.0434186 | I28: =VLOOKUP($A28,$A$17:$J$23,COLUMN(I5),0)/VLOOKUP($A28,$A$3:$J$9,COLUMN(I5),0) -> 1.0365 | J28: =VLOOKUP($A28,$A$17:$J$23,COLUMN(J5),0)/VLOOKUP($A28,$A$3:$J$9,COLUMN(J5),0) -> 0.97850485
A29: 华中 | B29: =VLOOKUP($A29,$A$17:$J$23,COLUMN(B6),0)/VLOOKUP($A29,$A$3:$J$9,COLUMN(B6),0) -> 0.91468 | C29: =VLOOKUP($A29,$A$17:$J$23,COLUMN(C6),0)/VLOOKUP($A29,$A$3:$J$9,COLUMN(C6),0) -> 0 | D29: =VLOOKUP($A29,$A$17:$J$23,COLUMN(D6),0)/VLOOKUP($A29,$A$3:$J$9,COLUMN(D6),0) -> 0.9235098 | E29: =VLOOKUP($A29,$A$17:$J$23,COLUMN(E6),0)/VLOOKUP($A29,$A$3:$J$9,COLUMN(E6),0) -> 0.93307407 | F29: =VLOOKUP($A29,$A$17:$J$23,COLUMN(F6),0)/VLOOKUP($A29,$A$3:$J$9,COLUMN(F6),0) -> 0.87505319 | G29: =VLOOKUP($A29,$A$17:$J$23,COLUMN(G6),0)/VLOOKUP($A29,$A$3:$J$9,COLUMN(G6),0) -> 0.80122414 | H29: =VLOOKUP($A29,$A$17:$J$23,COLUMN(H6),0)/VLOOKUP($A29,$A$3:$J$9,COLUMN(H6),0) -> 0.9065 | I29: =VLOOKUP($A29,$A$17:$J$23,COLUMN(I6),0)/VLOOKUP($A29,$A$3:$J$9,COLUMN(I6),0) -> 0.92130952 | J29: =VLOOKUP($A29,$A$17:$J$23,COLUMN(J6),0)/VLOOKUP($A29,$A$3:$J$9,COLUMN(J6),0) -> 0.80302771
A30: 西南 | B30: =VLOOKUP($A30,$A$17:$J$23,COLUMN(B7),0)/VLOOKUP($A30,$A$3:$J$9,COLUMN(B7),0) -> 1.1448462 | C30: =VLOOKUP($A30,$A$17:$J$23,COLUMN(C7),0)/VLOOKUP($A30,$A$3:$J$9,COLUMN(C7),0) -> 1.11928 | D30: =VLOOKUP($A30,$A$17:$J$23,COLUMN(D7),0)/VLOOKUP($A30,$A$3:$J$9,COLUMN(D7),0) -> 1.1266957 | E30: =VLOOKUP($A30,$A$17:$J$23,COLUMN(E7),0)/VLOOKUP($A30,$A$3:$J$9,COLUMN(E7),0) -> 1.4429123 | F30: =VLOOKUP($A30,$A$17:$J$23,COLUMN(F7),0)/VLOOKUP($A30,$A$3:$J$9,COLUMN(F7),0) -> 0.963375 | G30: =VLOOKUP($A30,$A$17:$J$23,COLUMN(G7),0)/VLOOKUP($A30,$A$3:$J$9,COLUMN(G7),0) -> 1.126087 | H30: =VLOOKUP($A30,$A$17:$J$23,COLUMN(H7),0)/VLOOKUP($A30,$A$3:$J$9,COLUMN(H7),0) -> 1.1376456 | I30: =VLOOKUP($A30,$A$17:$J$23,COLUMN(I7),0)/VLOOKUP($A30,$A$3:$J$9,COLUMN(I7),0) -> 1.1273667 | J30: =VLOOKUP($A30,$A$17:$J$23,COLUMN(J7),0)/VLOOKUP($A30,$A$3:$J$9,COLUMN(J7),0) -> 1.1679309
A31: 总计 | B31: =VLOOKUP($A31,$A$17:$J$23,COLUMN(B8),0)/VLOOKUP($A31,$A$3:$J$9,COLUMN(B8),0) -> 0.95353691 | C31: =VLOOKUP($A31,$A$17:$J$23,COLUMN(C8),0)/VLOOKUP($A31,$A$3:$J$9,COLUMN(C8),0) -> 0.58884681 | D31: =VLOOKUP($A31,$A$17:$J$23,COLUMN(D8),0)/VLOOKUP($A31,$A$3:$J$9,COLUMN(D8),0) -> 1.0408796 | E31: =VLOOKUP($A31,$A$17:$J$23,COLUMN(E8),0)/VLOOKUP($A31,$A$3:$J$9,COLUMN(E8),0) -> 1.1946154 | F31: =VLOOKUP($A31,$A$17:$J$23,COLUMN(F8),0)/VLOOKUP($A31,$A$3:$J$9,COLUMN(F8),0) -> 0.86329412 | G31: =VLOOKUP($A31,$A$17:$J$23,COLUMN(G8),0)/VLOOKUP($A31,$A$3:$J$9,COLUMN(G8),0) -> 0.94513506 | H31: =VLOOKUP($A31,$A$17:$J$23,COLUMN(H8),0)/VLOOKUP($A31,$A$3:$J$9,COLUMN(H8),0) -> 1.0264507 | I31: =VLOOKUP($A31,$A$17:$J$23,COLUMN(I8),0)/VLOOKUP($A31,$A$3:$J$9,COLUMN(I8),0) -> 1.021273 | J31: =VLOOKUP($A31,$A$17:$J$23,COLUMN(J8),0)/VLOOKUP($A31,$A$3:$J$9,COLUMN(J8),0) -> 0.95586887
B35: 实际金额 | C35: 目标金额 | D35: 日期
A36: 华北 | B36: =VLOOKUP($A36,$A$17:$J$22,2,0) -> 27938 | C36: =VLOOKUP($A36,$A$4:$J$8,2,0) -> 29000 | D36: 46023
A37: 华东 | B37: =VLOOKUP($A37,$A$17:$J$22,2,0) -> 22857 | C37: =VLOOKUP($A37,$A$4:$J$8,2,0) -> 23000 | D37: 46054
A38: 华南 | B38: =VLOOKUP($A38,$A$17:$J$22,2,0) -> 899 | C38: =VLOOKUP($A38,$A$4:$J$8,2,0) -> 8000 | D38: 46082
A39: 华中 | B39: =VLOOKUP($A39,$A$17:$J$22,2,0) -> 45734 | C39: =VLOOKUP($A39,$A$4:$J$8,2,0) -> 50000 | D39: 46113
A40: 西南 | B40: =VLOOKUP($A40,$A$17:$J$22,2,0) -> 44649 | C40: =VLOOKUP($A40,$A$4:$J$8,2,0) -> 39000 | D40: 46143
